Workbook

Sheet Overview
A1: City | B1: old P data | C1: Private School | E1: Charter | F1: Magnet | G1: Traditional | H1: Total Public School | I1: delta | J1: Charter % | K1: Magnet % | L1: Traditional %
A2: Atlanta | B2: 45 | C2: 48 | E2: =COUNTIF(Atlanta!D:D,"Charter") -> 13 | F2: =COUNTIF(Atlanta!D:D,"Magnet") -> 7 | G2: =COUNTIF(Atlanta!D:D,"Traditional") -> 35 | H2: =E2+F2+G2 -> 55 | I2: =H2-B2 -> 10 | J2: =E2/H2 -> 0.23636364 | K2: =F2/H2 -> 0.12727273 | L2: =G2/H2 -> 0.63636364
A3: Austin | B3: 37 | C3: 32 | E3: =COUNTIF(Austin!D:D,"Charter") -> 19 | F3: =COUNTIF(Austin!D:D,"Magnet") -> 2 | G3: =COUNTIF(Austin!D:D,"Traditional") -> 31 | H3: =E3+F3+G3 -> 52 | I3: =H3-B3 -> 15 | J3: =E3/H3 -> 0.36538462 | K3: =F3/H3 -> 0.038461538 | L3: =G3/H3 -> 0.59615385
A4: Bay Area | B4: 49 | C4: 31 | E4: =COUNTIF(Bayarea!D:D,"Charter") -> 16 | F4: =COUNTIF(Bayarea!D:D,"Magnet") -> 7 | G4: =COUNTIF(Bayarea!D:D,"Traditional") -> 47 | H4: =E4+F4+G4 -> 70 | I4: =H4-B4 -> 21 | J4: =E4/H4 -> 0.22857143 | K4: =F4/H4 -> 0.1 | L4: =G4/H4 -> 0.67142857
A5: Boston | B5: 37 | C5: 36 | E5: =COUNTIF(Boston!D:D,"Charter") -> 14 | F5: =COUNTIF(Boston!D:D,"Magnet") -> 21 | G5: =COUNTIF(Boston!D:D,"Traditional") -> 32 | H5: =E5+F5+G5 -> 67 | I5: =H5-B5 -> 30 | J5: =E5/H5 -> 0.20895522 | K5: =F5/H5 -> 0.31343284 | L5: =G5/H5 -> 0.47761194
A6: Charleston | B6: 33 | C6: 39 | E6: =COUNTIF(Charleston!D:D,"Charter") -> 10 | F6: =COUNTIF(Charleston!D:D,"Magnet") -> 3 | G6: =COUNTIF(Charleston!D:D,"Traditional") -> 27 | H6: =E6+F6+G6 -> 40 | I6: =H6-B6 -> 7 | J6: =E6/H6 -> 0.25 | K6: =F6/H6 -> 0.075 | L6: =G6/H6 -> 0.675
A7: Chicago | B7: 41 | C7: 25 | E7: =COUNTIF(Chicago!D:D,"Charter") -> 20 | F7: =COUNTIF(Chicago!D:D,"Magnet") -> 15 | G7: =COUNTIF(Chicago!D:D,"Traditional") -> 36 | H7: =E7+F7+G7 -> 71 | I7: =H7-B7 -> 30 | J7: =E7/H7 -> 0.28169014 | K7: =F7/H7 -> 0.21126761 | L7: =G7/H7 -> 0.50704225
A8: Cincinnati | B8: 36 | C8: 30 | E8: =COUNTIF(Cincinnati!D:D,"Charter") -> 2 | F8: =COUNTIF(Cincinnati!D:D,"Magnet") -> 3 | G8: =COUNTIF(Cincinnati!D:D,"Traditional") -> 34 | H8: =E8+F8+G8 -> 39 | I8: =H8-B8 -> 3 | J8: =E8/H8 -> 0.051282051 | K8: =F8/H8 -> 0.076923077 | L8: =G8/H8 -> 0.87179487
A9: Cleveland | B9: 49 | C9: 29 | E9: =COUNTIF(Cleveland!D:D,"Charter") -> 4 | F9: =COUNTIF(Cleveland!D:D,"Magnet") -> 4 | G9: =COUNTIF(Cleveland!D:D,"Traditional") -> 50 | H9: =E9+F9+G9 -> 58 | I9: =H9-B9 -> 9 | J9: =E9/H9 -> 0.068965517 | K9: =F9/H9 -> 0.068965517 | L9: =G9/H9 -> 0.86206897
A10: Dallas | B10: 47 | C10: 42 | E10: =COUNTIF(Dallas!D:D,"Charter") -> 3 | F10: =COUNTIF(Dallas!D:D,"Magnet") -> 7 | G10: =COUNTIF(Dallas!D:D,"Traditional") -> 42 | H10: =E10+F10+G10 -> 52 | I10: =H10-B10 -> 5 | J10: =E10/H10 -> 0.057692308 | K10: =F10/H10 -> 0.13461538 | L10: =G10/H10 -> 0.80769231
A11: DC | B11: 39 | C11: 34 | E11: =COUNTIF(DC!D:D,"Charter") -> 7 | F11: =COUNTIF(DC!D:D,"Magnet") -> 13 | G11: =COUNTIF(DC!D:D,"Traditional") -> 28 | H11: =E11+F11+G11 -> 48 | I11: =H11-B11 -> 9 | J11: =E11/H11 -> 0.14583333 | K11: =F11/H11 -> 0.27083333 | L11: =G11/H11 -> 0.58333333
A12: Denver | B12: 30 | C12: 28 | E12: =COUNTIF(Denver!D:D,"Charter") -> 9 | F12: =COUNTIF(Denver!D:D,"Magnet") -> 2 | G12: =COUNTIF(Denver!D:D,"Traditional") -> 27 | H12: =E12+F12+G12 -> 38 | I12: =H12-B12 -> 8 | J12: =E12/H12 -> 0.23684211 | K12: =F12/H12 -> 0.052631579 | L12: =G12/H12 -> 0.71052632
A13: Detroit | B13: 45 | C13: 36 | E13: =COUNTIF(Detroit!D:D,"Charter") -> 4 | F13: =COUNTIF(Detroit!D:D,"Magnet") -> 9 | G13: =COUNTIF(Detroit!D:D,"Traditional") -> 37 | H13: =E13+F13+G13 -> 50 | I13: =H13-B13 -> 5 | J13: =E13/H13 -> 0.08 | K13: =F13/H13 -> 0.18 | L13: =G13/H13 -> 0.74
A14: Hawaii | B14: 29 | C14: 37 | E14: =COUNTIF(Hawaii!D:D,"Charter") -> 4 | F14: =COUNTIF(Hawaii!D:D,"Magnet") -> 0 | G14: =COUNTIF(Hawaii!D:D,"Traditional") -> 28 | H14: =E14+F14+G14 -> 32 | I14: =H14-B14 -> 3 | J14: =E14/H14 -> 0.125 | K14: =F14/H14 -> 0 | L14: =G14/H14 -> 0.875
A15: Houston | B15: 31 | C15: 44 | E15: =COUNTIF(Houston!D:D,"Charter") -> 6 | F15: =COUNTIF(Houston!D:D,"Magnet") -> 10 | G15: =COUNTIF(Houston!D:D,"Traditional") -> 23 | H15: =E15+F15+G15 -> 39 | I15: =H15-B15 -> 8 | J15: =E15/H15 -> 0.15384615 | K15: =F15/H15 -> 0.25641026 | L15: =G15/H15 -> 0.58974359
A16: Indianapolis | B16: 39 | C16: 31 | E16: =COUNTIF(Indianapolis!D:D,"Charter") -> 4 | F16: =COUNTIF(Indianapolis!D:D,"Magnet") -> 3 | G16: =COUNTIF(Indianapolis!D:D,"Traditional") -> 34 | H16: =E16+F16+G16 -> 41 | I16: =H16-B16 -> 2 | J16: =E16/H16 -> 0.097560976 | K16: =F16/H16 -> 0.073170732 | L16: =G16/H16 -> 0.82926829
A17: Kansas City | B17: 49 | C17: 43 | E17: =COUNTIF(KansasCity!D:D,"Charter") -> 5 | F17: =COUNTIF(KansasCity!D:D,"Magnet") -> 2 | G17: =COUNTIF(KansasCity!D:D,"Traditional") -> 47 | H17: =E17+F17+G17 -> 54 | I17: =H17-B17 -> 5 | J17: =E17/H17 -> 0.092592593 | K17: =F17/H17 -> 0.037037037 | L17: =G17/H17 -> 0.87037037
A18: Los Angeles | B18: 46 | C18: 21 | E18: =COUNTIF(LA!D:D,"Charter") -> 7 | F18: =COUNTIF(LA!D:D,"Magnet") -> 9 | G18: =COUNTIF(LA!D:D,"Traditional") -> 39 | H18: =E18+F18+G18 -> 55 | I18: =H18-B18 -> 9 | J18: =E18/H18 -> 0.12727273 | K18: =F18/H18 -> 0.16363636 | L18: =G18/H18 -> 0.70909091
A19: Las Vegas | B19: 28 | C19: 22 | E19: =COUNTIF(LasVegas!C:C,"Charter") -> 4 | F19: =COUNTIF(LasVegas!C:C,"Magnet") -> 10 | G19: =COUNTIF(LasVegas!C:C,"Traditional") -> 21 | H19: =E19+F19+G19 -> 35 | I19: =H19-B19 -> 7 | J19: =E19/H19 -> 0.11428571 | K19: =F19/H19 -> 0.28571429 | L19: =G19/H19 -> 0.6
A20: Miami | B20: 44 | C20: 43 | E20: =COUNTIF(Miami!D:D,"Charter") -> 13 | F20: =COUNTIF(Miami!D:D,"Magnet") -> 16 | G20: =COUNTIF(Miami!D:D,"Traditional") -> 16 | H20: =E20+F20+G20 -> 45 | I20: =H20-B20 -> 1 | J20: =E20/H20 -> 0.28888889 | K20: =F20/H20 -> 0.35555556 | L20: =G20/H20 -> 0.35555556
A21: Milwaukee | B21: 43 | C21: 34 | E21: =COUNTIF(Milwaukee!D:D,"Charter") -> 2 | F21: =COUNTIF(Milwaukee!D:D,"Magnet") -> 4 | G21: =COUNTIF(Milwaukee!D:D,"Traditional") -> 37 | H21: =E21+F21+G21 -> 43 | I21: =H21-B21 -> 0 | J21: =E21/H21 -> 0.046511628 | K21: =F21/H21 -> 0.093023256 | L21: =G21/H21 -> 0.86046512
A22: Nashville | B22: 27 | C22: 40 | E22: =COUNTIF(Nashville!D:D,"Charter") -> 4 | F22: =COUNTIF(Nashville!D:D,"Magnet") -> 5 | G22: =COUNTIF(Nashville!D:D,"Traditional") -> 21 | H22: =E22+F22+G22 -> 30 | I22: =H22-B22 -> 3 | J22: =E22/H22 -> 0.13333333 | K22: =F22/H22 -> 0.16666667 | L22: =G22/H22 -> 0.7
A23: New Orleans | B23: 46 | C23: 37 | E23: =COUNTIF(NewOrleans!D:D,"Charter") -> 14 | F23: =COUNTIF(NewOrleans!D:D,"Magnet") -> 6 | G23: =COUNTIF(NewOrleans!D:D,"Traditional") -> 28 | H23: =E23+F23+G23 -> 48 | I23: =H23-B23 -> 2 | J23: =E23/H23 -> 0.29166667 | K23: =F23/H23 -> 0.125 | L23: =G23/H23 -> 0.58333333
A24: NYC | B24: 30 | C24: 31 | E24: =COUNTIF(NYC!D:D,"Charter") -> 4 | F24: =COUNTIF(NYC!D:D,"Magnet") -> 18 | G24: =COUNTIF(NYC!D:D,"Traditional") -> 12 | H24: =E24+F24+G24 -> 34 | I24: =H24-B24 -> 4 | J24: =E24/H24 -> 0.11764706 | K24: =F24/H24 -> 0.52941176 | L24: =G24/H24 -> 0.35294118
A25: Orlando | B25: 46 | C25: 33 | E25: =COUNTIF(Orlando!D:D,"Charter") -> 2 | F25: =COUNTIF(Orlando!D:D,"Magnet") -> 5 | G25: =COUNTIF(Orlando!D:D,"Traditional") -> 39 | H25: =E25+F25+G25 -> 46 | I25: =H25-B25 -> 0 | J25: =E25/H25 -> 0.043478261 | K25: =F25/H25 -> 0.10869565 | L25: =G25/H25 -> 0.84782609
A26: Philadelphia | B26: 48 | C26: 48 | E26: =COUNTIF(Philadelphia!D:D,"Charter") -> 9 | F26: =COUNTIF(Philadelphia!D:D,"Magnet") -> 12 | G26: =COUNTIF(Philadelphia!D:D,"Traditional") -> 35 | H26: =E26+F26+G26 -> 56 | I26: =H26-B26 -> 8 | J26: =E26/H26 -> 0.16071429 | K26: =F26/H26 -> 0.21428571 | L26: =G26/H26 -> 0.625
A27: Phoenix | B27: 49 | C27: 31 | E27: =COUNTIF(Phoenix!D:D,"Charter") -> 21 | F27: =COUNTIF(Phoenix!D:D,"Magnet") -> 2 | G27: =COUNTIF(Phoenix!D:D,"Traditional") -> 26 | H27: =E27+F27+G27 -> 49 | I27: =H27-B27 -> 0 | J27: =E27/H27 -> 0.42857143 | K27: =F27/H27 -> 0.040816327 | L27: =G27/H27 -> 0.53061224
A28: Portland | B28: 35 | C28: 34 | E28: =COUNTIF(Portland!D:D,"Charter") -> 3 | F28: =COUNTIF(Portland!D:D,"Magnet") -> 2 | G28: =COUNTIF(Portland!D:D,"Traditional") -> 34 | H28: =E28+F28+G28 -> 39 | I28: =H28-B28 -> 4 | J28: =E28/H28 -> 0.076923077 | K28: =F28/H28 -> 0.051282051 | L28: =G28/H28 -> 0.87179487
A29: San Antonio | B29: 48 | C29: 37 | E29: =COUNTIF(SanAntonio!D:D,"Charter") -> 7 | F29: =COUNTIF(SanAntonio!D:D,"Magnet") -> 10 | G29: =COUNTIF(SanAntonio!D:D,"Traditional") -> 31 | H29: =E29+F29+G29 -> 48 | I29: =H29-B29 -> 0 | J29: =E29/H29 -> 0.14583333 | K29: =F29/H29 -> 0.20833333 | L29: =G29/H29 -> 0.64583333
A30: San Diego | B30: 55 | C30: 26 | E30: =COUNTIF(SanDiego!D:D,"Charter") -> 11 | F30: =COUNTIF(SanDiego!D:D,"Magnet") -> 3 | G30: =COUNTIF(SanDiego!D:D,"Traditional") -> 41 | H30: =E30+F30+G30 -> 55 | I30: =H30-B30 -> 0 | J30: =E30/H30 -> 0.2 | K30: =F30/H30 -> 0.054545455 | L30: =G30/H30 -> 0.74545455
A31: Seattle | B31: 39 | C31: 36 | E31: =COUNTIF(Seattle!D:D,"Charter") -> 6 | F31: =COUNTIF(Seattle!D:D,"Magnet") -> 5 | G31: =COUNTIF(Seattle!D:D,"Traditional") -> 34 | H31: =E31+F31+G31 -> 45 | I31: =H31-B31 -> 6 | J31: =E31/H31 -> 0.13333333 | K31: =F31/H31 -> 0.11111111 | L31: =G31/H31 -> 0.75555556

Sheet T25_Public_School
A1: Atlanta | B1: Austin | C1: Bay Area | D1: Boston | E1: Charleston | F1: Chicago | G1: Cincinnati | H1: Cleveland | I1: Dallas | J1: DC | K1: Denver | L1: Detroit | M1: Hawaii | N1: Houston | O1: Indianapolis | P1: Kansas City | Q1: Los Angeles | R1: Las Vegas | S1: Miami | T1: Milwaukee | U1: Nashville | V1: New Orleans | W1: NYC | X1: Orlando | Y1: Philadelphia | Z1: Phoenix | AA1: Portland | AB1: San Antonio | AC1: San Diego | AD1: Seattle
A2: 0.55 | B2: 0.4 | C2: 0.28 | D2: 0.24 | E2: 0.5 | F2: 0.18 | G2: 0.35 | H2: 0.4 | I2: 0.35 | J2: 0.7 | K2: 0.48 | L2: 0.45 | M2: 0.28 | N2: 0.38 | O2: 0.3 | P2: 0.38 | Q2: 0.28 | R2: 0.18 | S2: 0.45 | T2: 0.3 | U2: 0.45 | V2: 0.45 | W2: 0.45 | X2: 0.4 | Y2: 0.4 | Z2: 0.6 | AA2: 0.5 | AB2: 0.45 | AC2: 0.28 | AD2: 0.5
A3: 0.4 | B3: 0.3 | C3: 0.26 | D3: 0.25 | E3: 0.35 | F3: 0.16 | G3: 0.32 | H3: 0.33 | I3: 0.3 | J3: 0.32 | K3: 0.45 | L3: 0.38 | M3: 0.25 | N3: 0.32 | O3: 0.32 | P3: 0.35 | Q3: 0.24 | R3: 0.14 | S3: 0.38 | T3: 0.28 | U3: 0.42 | V3: 0.4 | W3: 0.3 | X3: 0.35 | Y3: 0.35 | Z3: 0.58 | AA3: 0.45 | AB3: 0.35 | AC3: 0.25 | AD3: 0.55
A4: 0.39 | B4: 0.28 | C4: 0.25 | D4: 0.22 | E4: 0.28 | F4: 0.15 | G4: 0.26 | H4: 0.35 | I4: 0.25 | J4: 0.28 | K4: 0.36 | L4: 0.32 | M4: 0.22 | N4: 0.28 | O4: 0.25 | P4: 0.33 | Q4: 0.22 | R4: 0.11 | S4: 0.4 | T4: 0.25 | U4: 0.4 | V4: 0.35 | W4: 0.35 | X4: 0.3 | Y4: 0.38 | Z4: 0.57 | AA4: 0.4 | AB4: 0.3 | AC4: 0.22 | AD4: 0.45
A5: 0.38 | B5: 0.25 | C5: 0.24 | D5: 0.2 | E5: 0.25 | F5: 0.15 | G5: 0.3 | H5: 0.3 | I5: 0.22 | J5: 0.25 | K5: 0.38 | L5: 0.35 | M5: 0.2 | N5: 0.22 | O5: 0.28 | P5: 0.3 | Q5: 0.25 | R5: 0.12 | S5: 0.35 | T5: 0.22 | U5: 0.38 | V5: 0.38 | W5: 0.42 | X5: 0.28 | Y5: 0.32 | Z5: 0.56 | AA5: 0.33 | AB5: 0.25 | AC5: 0.2 | AD5: 0.42
A6: 0.35 | B6: 0.22 | C6: 0.22 | D6: 0.19 | E6: 0.19 | F6: 0.14 | G6: 0.28 | H6: 0.28 | I6: 0.19 | J6: 0.24 | K6: 0.35 | L6: 0.3 | M6: 0.2 | N6: 0.2 | O6: 0.26 | P6: 0.32 | Q6: 0.2 | R6: 0.1 | S6: 0.32 | T6: 0.2 | U6: 0.35 | V6: 0.3 | W6: 0.4 | X6: 0.28 | Y6: 0.3 | Z6: 0.55 | AA6: 0.38 | AB6: 0.22 | AC6: 0.18 | AD6: 0.38
A7: 0.36 | B7: 0.2 | C7: 0.19 | D7: 0.18 | E7: 0.2 | F7: 0.13 | G7: 0.24 | H7: 0.27 | I7: 0.24 | J7: 0.22 | K7: 0.33 | L7: 0.28 | M7: 0.18 | N7: 0.19 | O7: 0.28 | P7: 0.29 | Q7: 0.22 | R7: 0.1 | S7: 0.3 | T7: 0.18 | U7: 0.35 | V7: 0.28 | W7: 0.35 | X7: 0.25 | Y7: 0.3 | Z7: 0.54 | AA7: 0.36 | AB7: 0.28 | AC7: 0.17 | AD7: 0.4
A8: 0.34 | B8: 0.16 | C8: 0.2 | D8: 0.18 | E8: 0.18 | F8: 0.12 | G8: 0.22 | H8: 0.26 | I8: 0.2 | J8: 0.26 | K8: 0.2 | L8: 0.3 | M8: 0.18 | N8: 0.2 | O8: 0.23 | P8: 0.27 | Q8: 0.2 | R8: 0.09 | S8: 0.3 | T8: 0.2 | U8: 0.3 | V8: 0.25 | W8: 0.32 | X8: 0.22 | Y8: 0.28 | Z8: 0.54 | AA8: 0.3 | AB8: 0.2 | AC8: 0.16 | AD8: 0.35
A9: 0.28 | B9: 0.18 | C9: 0.2 | D9: 0.17 | E9: 0.17 | F9: 0.11 | G9: 0.2 | H9: 0.25 | I9: 0.18 | J9: 0.24 | K9: 0.32 | L9: 0.26 | M9: 0.15 | N9: 0.18 | O9: 0.22 | P9: 0.26 | Q9: 0.18 | R9: 0.09 | S9: 0.28 | T9: 0.16 | U9: 0.32 | V9: 0.22 | W9: 0.3 | X9: 0.2 | Y9: 0.24 | Z9: 0.53 | AA9: 0.35 | AB9: 0.22 | AC9: 0.15 | AD9: 0.3
A10: 0.32 | B10: 0.16 | C10: 0.18 | D10: 0.19 | E10: 0.18 | F10: 0.1 | G10: 0.18 | H10: 0.23 | I10: 0.17 | J10: 0.22 | K10: 0.3 | L10: 0.28 | M10: 0.14 | N10: 0.18 | O10: 0.24 | P10: 0.28 | Q10: 0.18 | R10: 0.09 | S10: 0.25 | T10: 0.2 | U10: 0.28 | V10: 0.2 | W10: 0.38 | X10: 0.2 | Y10: 0.22 | Z10: 0.52 | AA10: 0.25 | AB10: 0.2 | AC10: 0.15 | AD10: 0.28
A11: 0.3 | B11: 0.14 | C11: 0.19 | D11: 0.18 | E11: 0.16 | F11: 0.12 | G11: 0.18 | H11: 0.24 | I11: 0.16 | J11: 0.21 | K11: 0.3 | L11: 0.27 | M11: 0.14 | N11: 0.16 | O11: 0.22 | P11: 0.25 | Q11: 0.15 | R11: 0.08 | S11: 0.22 | T11: 0.15 | U11: 0.28 | V11: 0.18 | W11: 0.35 | X11: 0.2 | Y11: 0.25 | Z11: 0.38 | AA11: 0.32 | AB11: 0.18 | AC11: 0.14 | AD11: 0.28
A12: 0.31 | B12: 0.15 | C12: 0.17 | D12: 0.16 | E12: 0.15 | F12: 0.12 | G12: 0.17 | H12: 0.22 | I12: 0.2 | J12: 0.22 | K12: 0.27 | L12: 0.26 | M12: 0.15 | N12: 0.17 | O12: 0.2 | P12: 0.25 | Q12: 0.17 | R12: 0.08 | S12: 0.22 | T12: 0.18 | U12: 0.25 | V12: 0.18 | W12: 0.25 | X12: 0.18 | Y12: 0.17 | Z12: 0.5 | AA12: 0.28 | AB12: 0.16 | AC12: 0.13 | AD12: 0.25
A13: 0.27 | B13: 0.15 | C13: 0.18 | D13: 0.17 | E13: 0.15 | F13: 0.11 | G13: 0.16 | H13: 0.2 | I13: 0.18 | J13: 0.22 | K13: 0.29 | L13: 0.25 | M13: 0.12 | N13: 0.14 | O13: 0.18 | P13: 0.24 | Q13: 0.16 | R13: 0.05 | S13: 0.2 | T13: 0.14 | U13: 0.26 | V13: 0.17 | W13: 0.28 | X13: 0.18 | Y13: 0.2 | Z13: 0.37 | AA13: 0.24 | AB13: 0.18 | AC13: 0.12 | AD13: 0.26
... A31: 0.21 | B31: 0.08 | C31: 0.12 | D31: 0.1 | E31: 0.04 | F31: 0.07 | G31: 0.07 | H31: 0.08 | I31: 0.1 | J31: 0.14 | K31: 0.15 | L31: 0.14 | M31: 0.06 | N31: 0.1 | O31: 0.1 | P31: 0.14 | Q31: 0.09 | R31: 0.01 | S31: 0.12 | T31: 0.08 | U31: 0.06 | V31: 0.08 | W31: 0.05 | X31: 0.1 | Y31: 0.18 | Z31: 0.18 | AA31: 0.12 | AB31: 0.08 | AC31: 0.07 | AD31: 0.12
A32: 0.22 | B32: 0.07 | C32: 0.11 | D32: 0.1 | E32: 0.04 | F32: 0.08 | G32: 0.07 | H32: 0.09 | I32: 0.09 | J32: 0.12 | K32: 0.14 | L32: 0.13 | M32: 0.05 | N32: 0.09 | O32: 0.11 | P32: 0.13 | Q32: 0.08 | R32: 0.01 | S32: 0.12 | T32: 0.08 | V32: 0.07 | W32: 0.05 | X32: 0.08 | Y32: 0.13 | Z32: 0.15 | AA32: 0.1 | AB32: 0.08 | AC32: 0.05 | AD32: 0.11
A33: 0.2 | B33: 0.07 | C33: 0.1 | D33: 0.12 | E33: 0.04 | F33: 0.08 | G33: 0.06 | H33: 0.08 | I33: 0.1 | J33: 0.1 | K33: 0.12 | L33: 0.12 | M33: 0.05 | N33: 0.1 | O33: 0.1 | P33: 0.14 | Q33: 0.07 | R33: 0.01 | S33: 0.12 | T33: 0.1 | V33: 0.08 | W33: 0.04 | X33: 0.09 | Y33: 0.12 | Z33: 0.17 | AA33: 0.1 | AB33: 0.08 | AC33: 0.06 | AD33: 0.1
A34: 0.2 | B34: 0.06 | C34: 0.1 | D34: 0.11 | E34: 0.04 | F34: 0.08 | G34: 0.06 | H34: 0.09 | I34: 0.09 | J34: 0.13 | K34: 0.1 | L34: 0.11 | N34: 0.1 | O34: 0.09 | P34: 0.15 | Q34: 0.08 | R34: 0.01 | S34: 0.12 | T34: 0.08 | V34: 0.07 | W34: 0.03 | X34: 0.08 | Y34: 0.12 | Z34: 0.18 | AA34: 0.09 | AB34: 0.08 | AC34: 0.06 | AD34: 0.1
A35: 0.19 | B35: 0.07 | C35: 0.1 | D35: 0.09 | E35: 0.03 | F35: 0.08 | G35: 0.05 | H35: 0.1 | I35: 0.09 | J35: 0.11 | K35: 0.1 | L35: 0.12 | N35: 0.08 | O35: 0.1 | P35: 0.12 | Q35: 0.07 | R35: 0.01 | S35: 0.11 | T35: 0.07 | V35: 0.06 | W35: 0.02 | X35: 0.08 | Y35: 0.15 | Z35: 0.19 | AA35: 0.09 | AB35: 0.09 | AC35: 0.06 | AD35: 0.1
A36: 0.18 | B36: 0.06 | C36: 0.1 | D36: 0.1 | E36: 0.03 | F36: 0.08 | G36: 0.04 | H36: 0.08 | I36: 0.09 | J36: 0.1 | K36: 0.08 | L36: 0.15 | N36: 0.09 | O36: 0.09 | P36: 0.12 | Q36: 0.08 | R36: 0.01 | S36: 0.1 | T36: 0.07 | V36: 0.06 | X36: 0.07 | Y36: 0.12 | Z36: 0.16 | AA36: 0.08 | AB36: 0.1 | AC36: 0.05 | AD36: 0.08
A37: 0.16 | B37: 0.06 | C37: 0.1 | D37: 0.11 | E37: 0.02 | F37: 0.07 | G37: 0.04 | H37: 0.07 | I37: 0.08 | J37: 0.12 | K37: 0.06 | L37: 0.12 | N37: 0.07 | O37: 0.08 | P37: 0.11 | Q37: 0.08 | S37: 0.1 | T37: 0.07 | V37: 0.06 | X37: 0.07 | Y37: 0.1 | Z37: 0.16 | AA37: 0.07 | AB37: 0.08 | AC37: 0.05 | AD37: 0.09
A38: 0.15 | B38: 0.06 | C38: 0.09 | D38: 0.1 | E38: 0.02 | F38: 0.08 | G38: 0.02 | H38: 0.07 | I38: 0.08 | J38: 0.08 | K38: 0.05 | L38: 0.11 | N38: 0.08 | O38: 0.08 | P38: 0.11 | Q38: 0.07 | S38: 0.1 | T38: 0.06 | V38: 0.06 | X38: 0.07 | Y38: 0.11 | Z38: 0.15 | AA38: 0.06 | AB38: 0.07 | AC38: 0.05 | AD38: 0.07
A39: 0.14 | B39: 0.06 | C39: 0.09 | D39: 0.09 | E39: 0.03 | F39: 0.07 | G39: 0.03 | H39: 0.08 | I39: 0.08 | J39: 0.1 | K39: 0.04 | L39: 0.1 | N39: 0.06 | O39: 0.1 | P39: 0.1 | Q39: 0.07 | S39: 0.1 | T39: 0.07 | V39: 0.06 | X39: 0.06 | Y39: 0.12 | Z39: 0.14 | AA39: 0.06 | AB39: 0.07 | AC39: 0.05 | AD39: 0.08
A40: 0.13 | B40: 0.06 | C40: 0.09 | D40: 0.08 | E40: 0.02 | F40: 0.08 | G40: 0.01 | H40: 0.07 | I40: 0.08 | J40: 0.06 | L40: 0.14 | N40: 0.04 | O40: 0.07 | P40: 0.12 | Q40: 0.06 | S40: 0.09 | T40: 0.06 | V40: 0.05 | X40: 0.06 | Y40: 0.12 | Z40: 0.14 | AA40: 0.05 | AB40: 0.07 | AC40: 0.05 | AD40: 0.06
A41: 0.15 | B41: 0.06 | C41: 0.08 | D41: 0.09 | E41: 0.01 | F41: 0.07 | H41: 0.06 | I41: 0.07 | J41: 0.07 | L41: 0.11 | O41: 0.07 | P41: 0.1 | Q41: 0.05 | S41: 0.08 | T41: 0.06 | V41: 0.05 | X41: 0.06 | Y41: 0.11 | Z41: 0.13 | AB41: 0.07 | AC41: 0.05 | AD41: 0.08
A42: 0.12 | B42: 0.05 | C42: 0.08 | D42: 0.09 | F42: 0.07 | H42: 0.05 | I42: 0.08 | J42: 0.08 | L42: 0.09 | O42: 0.05 | P42: 0.1 | Q42: 0.05 | S42: 0.09 | T42: 0.06 | V42: 0.05 | X42: 0.06 | Y42: 0.12 | Z42: 0.12 | AB42: 0.06 | AC42: 0.04 | AD42: 0.07
A43: 0.12 | B43: 0.05 | C43: 0.08 | D43: 0.08 | F43: 0.07 | H43: 0.06 | I43: 0.07 | J43: 0.08 | L43: 0.1 | P43: 0.09 | Q43: 0.04 | S43: 0.08 | T43: 0.05 | V43: 0.05 | X43: 0.05 | Y43: 0.09 | Z43: 0.12 | AB43: 0.06 | AC43: 0.04 | AD43: 0.06
A44: 0.1 | B44: 0.05 | C44: 0.09 | D44: 0.08 | F44: 0.07 | H44: 0.06 | I44: 0.07 | J44: 0.08 | L44: 0.09 | P44: 0.08 | Q44: 0.04 | S44: 0.08 | T44: 0.05 | V44: 0.04 | X44: 0.05 | Y44: 0.1 | Z44: 0.11 | AB44: 0.06 | AC44: 0.04 | AD44: 0.05
A45: 0.1 | B45: 0.04 | C45: 0.08 | D45: 0.05 | F45: 0.07 | H45: 0.06 | I45: 0.07 | J45: 0.07 | L45: 0.08 | P45: 0.08 | Q45: 0.04 | S45: 0.07 | V45: 0.04 | X45: 0.05 | Y45: 0.1 | Z45: 0.1 | AB45: 0.05 | AC45: 0.04 | AD45: 0.03
A46: 0.09 | B46: 0.04 | C46: 0.07 | D46: 0.07 | F46: 0.07 | H46: 0.05 | I46: 0.07 | J46: 0.07 | L46: 0.09 | P46: 0.07 | Q46: 0.03 | S46: 0.07 | V46: 0.04 | X46: 0.04 | Y46: 0.08 | Z46: 0.1 | AB46: 0.05 | AC46: 0.04 | AD46: 0.02
A47: 0.08 | B47: 0.03 | C47: 0.07 | D47: 0.06 | F47: 0.06 | H47: 0.05 | I47: 0.07 | J47: 0.06 | L47: 0.08 | P47: 0.07 | Q47: 0.03 | V47: 0.04 | X47: 0.04 | Y47: 0.1 | Z47: 0.09 | AB47: 0.04 | AC47: 0.04
A48: 0.1 | B48: 0.03 | C48: 0.07 | D48: 0.05 | F48: 0.07 | H48: 0.05 | I48: 0.06 | J48: 0.06 | L48: 0.08 | P48: 0.06 | Q48: 0.02 | V48: 0.04 | Y48: 0.09 | Z48: 0.08 | AB48: 0.04 | AC48: 0.03
A49: 0.07 | B49: 0.02 | C49: 0.06 | D49: 0.03 | F49: 0.07 | H49: 0.05 | I49: 0.06 | J49: 0.05 | L49: 0.06 | P49: 0.08 | Q49: 0.02 | V49: 0.03 | Y49: 0.08 | Z49: 0.08 | AB49: 0.03 | AC49: 0.03
A50: 0.08 | B50: 0.02 | C50: 0.06 | D50: 0.04 | F50: 0.07 | H50: 0.04 | I50: 0.05 | L50: 0.07 | P50: 0.06 | Q50: 0.02 | Y50: 0.09 | Z50: 0.07 | AC50: 0.02
A51: 0.08 | B51: 0.02 | C51: 0.06 | D51: 0.04 | F51: 0.07 | H51: 0.04 | I51: 0.05 | L51: 0.05 | P51: 0.05 | Q51: 0.02 | Y51: 0.1 | AC51: 0.03
A52: 0.08 | B52: 0.01 | C52: 0.06 | D52: 0.03 | F52: 0.07 | H52: 0.07 | I52: 0.05 | P52: 0.05 | Q52: 0.02 | Y52: 0.08 | AC52: 0.02
A53: 0.05 | B53: 0.01 | C53: 0.05 | D53: 0.03 | F53: 0.07 | H53: 0.04 | I53: 0.04 | P53: 0.04 | Q53: 0.02 | Y53: 0.08 | AC53: 0.02
A54: 0.05 | C54: 0.05 | D54: 0.02 | F54: 0.07 | H54: 0.04 | P54: 0.04 | Q54: 0.01 | Y54: 0.08 | AC54: 0.02
A55: 0.04 | C55: 0.05 | D55: 0.02 | F55: 0.06 | H55: 0.03 | P55: 0.05 | Q55: 0.02 | Y55: 0.07 | AC55: 0.01
A56: 0.03 | C56: 0.05 | D56: 0.02 | F56: 0.06 | H56: 0.03 | Q56: 0.01 | Y56: 0.07 | AC56: 0.01
C57: 0.05 | D57: 0.02 | F57: 0.06 | H57: 0.03 | Y57: 0.07
...

Sheet T25_Public_School_T
A1: Atlanta | B1: 0.55 | C1: 0.4 | D1: 0.39 | E1: 0.38 | F1: 0.35 | G1: 0.36 | H1: 0.34 | I1: 0.28 | J1: 0.32 | K1: 0.3 | L1: 0.31 | M1: 0.27 | N1: 0.29 | O1: 0.3 | P1: 0.28 | Q1: 0.2 | R1: 0.3 | S1: 0.25 | T1: 0.28 | U1: 0.26 | V1: 0.27 | W1: 0.25 | X1: 0.26 | Y1: 0.24 | Z1: 0.28 | AA1: 0.22 | AB1: 0.23 | AC1: 0.24 | AD1: 0.22 | AE1: 0.21 | AF1: 0.22 | AG1: 0.2 | AH1: 0.2 | AI1: 0.19 | AJ1: 0.18 | AK1: 0.16 | AL1: 0.15 | AM1: 0.14 | AN1: 0.13 | AO1: 0.15 | AP1: 0.12 | AQ1: 0.12 | AR1: 0.1 | AS1: 0.1 | AT1: 0.09 | AU1: 0.08 | AV1: 0.1 | AW1: 0.07 | AX1: 0.08 | AY1: 0.08 | AZ1: 0.08 | BA1: 0.05 | BB1: 0.05 | BC1: 0.04 | BD1: 0.03
A2: Austin | B2: 0.4 | C2: 0.3 | D2: 0.28 | E2: 0.25 | F2: 0.22 | G2: 0.2 | H2: 0.16 | I2: 0.18 | J2: 0.16 | K2: 0.14 | L2: 0.15 | M2: 0.15 | N2: 0.12 | O2: 0.14 | P2: 0.14 | Q2: 0.12 | R2: 0.11 | S2: 0.13 | T2: 0.1 | U2: 0.12 | V2: 0.12 | W2: 0.1 | X2: 0.09 | Y2: 0.09 | Z2: 0.08 | AA2: 0.1 | AB2: 0.08 | AC2: 0.09 | AD2: 0.07 | AE2: 0.08 | AF2: 0.07 | AG2: 0.07 | AH2: 0.06 | AI2: 0.07 | AJ2: 0.06 | AK2: 0.06 | AL2: 0.06 | AM2: 0.06 | AN2: 0.06 | AO2: 0.06 | AP2: 0.05 | AQ2: 0.05 | AR2: 0.05 | AS2: 0.04 | AT2: 0.04 | AU2: 0.03 | AV2: 0.03 | AW2: 0.02 | AX2: 0.02 | AY2: 0.02 | AZ2: 0.01 | BA2: 0.01
A3: Bay Area | B3: 0.28 | C3: 0.26 | D3: 0.25 | E3: 0.24 | F3: 0.22 | G3: 0.19 | H3: 0.2 | I3: 0.2 | J3: 0.18 | K3: 0.19 | L3: 0.17 | M3: 0.18 | N3: 0.16 | O3: 0.15 | P3: 0.15 | Q3: 0.14 | R3: 0.15 | S3: 0.15 | T3: 0.14 | U3: 0.14 | V3: 0.12 | W3: 0.14 | X3: 0.11 | Y3: 0.13 | Z3: 0.12 | AA3: 0.11 | AB3: 0.12 | AC3: 0.12 | AD3: 0.11 | AE3: 0.12 | AF3: 0.11 | AG3: 0.1 | AH3: 0.1 | AI3: 0.1 | AJ3: 0.1 | AK3: 0.1 | AL3: 0.09 | AM3: 0.09 | AN3: 0.09 | AO3: 0.08 | AP3: 0.08 | AQ3: 0.08 | AR3: 0.09 | AS3: 0.08 | AT3: 0.07 | AU3: 0.07 | AV3: 0.07 | AW3: 0.06 | AX3: 0.06 | AY3: 0.06 | AZ3: 0.06 | BA3: 0.05 | BB3: 0.05 | BC3: 0.05 | BD3: 0.05 | BE3: 0.05 | BF3: 0.04 | BG3: 0.04 | BH3: 0.04 | BI3: 0.03 | BJ3: 0.03 | BK3: 0.02 | BL3: 0.02 | BM3: 0.02 | BN3: 0.02 | BO3: 0.02 | BP3: 0.02 | BQ3: 0.01 | BR3: 0.01 | BS3: 0.01
A4: Boston | B4: 0.24 | C4: 0.25 | D4: 0.22 | E4: 0.2 | F4: 0.19 | G4: 0.18 | H4: 0.18 | I4: 0.17 | J4: 0.19 | K4: 0.18 | L4: 0.16 | M4: 0.17 | N4: 0.17 | O4: 0.17 | P4: 0.17 | Q4: 0.16 | R4: 0.16 | S4: 0.15 | T4: 0.16 | U4: 0.15 | V4: 0.14 | W4: 0.14 | X4: 0.13 | Y4: 0.14 | Z4: 0.15 | AA4: 0.12 | AB4: 0.12 | AC4: 0.12 | AD4: 0.13 | AE4: 0.1 | AF4: 0.1 | AG4: 0.12 | AH4: 0.11 | AI4: 0.09 | AJ4: 0.1 | AK4: 0.11 | AL4: 0.1 | AM4: 0.09 | AN4: 0.08 | AO4: 0.09 | AP4: 0.09 | AQ4: 0.08 | AR4: 0.08 | AS4: 0.05 | AT4: 0.07 | AU4: 0.06 | AV4: 0.05 | AW4: 0.03 | AX4: 0.04 | AY4: 0.04 | AZ4: 0.03 | BA4: 0.03 | BB4: 0.02 | BC4: 0.02 | BD4: 0.02 | BE4: 0.02 | BF4: 0.02 | BG4: 0.01 | BH4: 0.02 | BI4: 0.01 | BJ4: 0.01 | BK4: 0.01 | BL4: 0.01 | BM4: 0.01 | BN4: 0.01 | BO4: 0.01 | BP4: 0
A5: Charleston | B5: 0.5 | C5: 0.35 | D5: 0.28 | E5: 0.25 | F5: 0.19 | G5: 0.2 | H5: 0.18 | I5: 0.17 | J5: 0.18 | K5: 0.16 | L5: 0.15 | M5: 0.15 | N5: 0.14 | O5: 0.14 | P5: 0.14 | Q5: 0.13 | R5: 0.12 | S5: 0.12 | T5: 0.11 | U5: 0.1 | V5: 0.09 | W5: 0.08 | X5: 0.08 | Y5: 0.07 | Z5: 0.06 | AA5: 0.07 | AB5: 0.06 | AC5: 0.05 | AD5: 0.05 | AE5: 0.04 | AF5: 0.04 | AG5: 0.04 | AH5: 0.04 | AI5: 0.03 | AJ5: 0.03 | AK5: 0.02 | AL5: 0.02 | AM5: 0.03 | AN5: 0.02 | AO5: 0.01
A6: Chicago | B6: 0.18 | C6: 0.16 | D6: 0.15 | E6: 0.15 | F6: 0.14 | G6: 0.13 | H6: 0.12 | I6: 0.11 | J6: 0.1 | K6: 0.12 | L6: 0.12 | M6: 0.11 | N6: 0.1 | O6: 0.09 | P6: 0.1 | Q6: 0.1 | R6: 0.1 | S6: 0.09 | T6: 0.09 | U6: 0.09 | V6: 0.08 | W6: 0.09 | X6: 0.09 | Y6: 0.08 | Z6: 0.08 | AA6: 0.08 | AB6: 0.09 | AC6: 0.08 | AD6: 0.08 | AE6: 0.07 | AF6: 0.08 | AG6: 0.08 | AH6: 0.08 | AI6: 0.08 | AJ6: 0.08 | AK6: 0.07 | AL6: 0.08 | AM6: 0.07 | AN6: 0.08 | AO6: 0.07 | AP6: 0.07 | AQ6: 0.07 | AR6: 0.07 | AS6: 0.07 | AT6: 0.07 | AU6: 0.06 | AV6: 0.07 | AW6: 0.07 | AX6: 0.07 | AY6: 0.07 | AZ6: 0.07 | BA6: 0.07 | BB6: 0.07 | BC6: 0.06 | BD6: 0.06 | BE6: 0.06 | BF6: 0.05 | BG6: 0.05 | BH6: 0.06 | BI6: 0.04 | BJ6: 0.05 | BK6: 0.04 | BL6: 0.04 | BM6: 0.03 | BN6: 0.03 | BO6: 0.03 | BP6: 0.02 | BQ6: 0.02 | BR6: 0.02 | BS6: 0.01 | BT6: 0.01
A7: Cincinnati | B7: 0.35 | C7: 0.32 | D7: 0.26 | E7: 0.3 | F7: 0.28 | G7: 0.24 | H7: 0.22 | I7: 0.2 | J7: 0.18 | K7: 0.18 | L7: 0.17 | M7: 0.16 | N7: 0.15 | O7: 0.14 | P7: 0.14 | Q7: 0.15 | R7: 0.13 | S7: 0.12 | T7: 0.11 | U7: 0.1 | V7: 0.1 | W7: 0.09 | X7: 0.09 | Y7: 0.09 | Z7: 0.08 | AA7: 0.08 | AB7: 0.08 | AC7: 0.08 | AD7: 0.07 | AE7: 0.07 | AF7: 0.07 | AG7: 0.06 | AH7: 0.06 | AI7: 0.05 | AJ7: 0.04 | AK7: 0.04 | AL7: 0.02 | AM7: 0.03 | AN7: 0.01
A8: Cleveland | B8: 0.4 | C8: 0.33 | D8: 0.35 | E8: 0.3 | F8: 0.28 | G8: 0.27 | H8: 0.26 | I8: 0.25 | J8: 0.23 | K8: 0.24 | L8: 0.22 | M8: 0.2 | N8: 0.19 | O8: 0.2 | P8: 0.18 | Q8: 0.17 | R8: 0.16 | S8: 0.15 | T8: 0.14 | U8: 0.15 | V8: 0.14 | W8: 0.13 | X8: 0.11 | Y8: 0.12 | Z8: 0.12 | AA8: 0.1 | AB8: 0.1 | AC8: 0.11 | AD8: 0.09 | AE8: 0.08 | AF8: 0.09 | AG8: 0.08 | AH8: 0.09 | AI8: 0.1 | AJ8: 0.08 | AK8: 0.07 | AL8: 0.07 | AM8: 0.08 | AN8: 0.07 | AO8: 0.06 | AP8: 0.05 | AQ8: 0.06 | AR8: 0.06 | AS8: 0.06 | AT8: 0.05 | AU8: 0.05 | AV8: 0.05 | AW8: 0.05 | AX8: 0.04 | AY8: 0.04 | AZ8: 0.07 | BA8: 0.04 | BB8: 0.04 | BC8: 0.03 | BD8: 0.03 | BE8: 0.03 | BF8: 0.02 | BG8: 0.02
A9: Dallas | B9: 0.35 | C9: 0.3 | D9: 0.25 | E9: 0.22 | F9: 0.19 | G9: 0.24 | H9: 0.2 | I9: 0.18 | J9: 0.17 | K9: 0.16 | L9: 0.2 | M9: 0.18 | N9: 0.15 | O9: 0.14 | P9: 0.15 | Q9: 0.13 | R9: 0.13 | S9: 0.13 | T9: 0.12 | U9: 0.14 | V9: 0.12 | W9: 0.12 | X9: 0.11 | Y9: 0.15 | Z9: 0.11 | AA9: 0.1 | AB9: 0.1 | AC9: 0.1 | AD9: 0.1 | AE9: 0.1 | AF9: 0.09 | AG9: 0.1 | AH9: 0.09 | AI9: 0.09 | AJ9: 0.09 | AK9: 0.08 | AL9: 0.08 | AM9: 0.08 | AN9: 0.08 | AO9: 0.07 | AP9: 0.08 | AQ9: 0.07 | AR9: 0.07 | AS9: 0.07 | AT9: 0.07 | AU9: 0.07 | AV9: 0.06 | AW9: 0.06 | AX9: 0.05 | AY9: 0.05 | AZ9: 0.05 | BA9: 0.04
A10: DC | B10: 0.7 | C10: 0.32 | D10: 0.28 | E10: 0.25 | F10: 0.24 | G10: 0.22 | H10: 0.26 | I10: 0.24 | J10: 0.22 | K10: 0.21 | L10: 0.22 | M10: 0.22 | N10: 0.2 | O10: 0.2 | P10: 0.19 | Q10: 0.18 | R10: 0.18 | S10: 0.16 | T10: 0.16 | U10: 0.16 | V10: 0.15 | W10: 0.12 | X10: 0.14 | Y10: 0.14 | Z10: 0.1 | AA10: 0.15 | AB10: 0.14 | AC10: 0.14 | AD10: 0.18 | AE10: 0.14 | AF10: 0.12 | AG10: 0.1 | AH10: 0.13 | AI10: 0.11 | AJ10: 0.1 | AK10: 0.12 | AL10: 0.08 | AM10: 0.1 | AN10: 0.06 | AO10: 0.07 | AP10: 0.08 | AQ10: 0.08 | AR10: 0.08 | AS10: 0.07 | AT10: 0.07 | AU10: 0.06 | AV10: 0.06 | AW10: 0.05
A11: Denver | B11: 0.48 | C11: 0.45 | D11: 0.36 | E11: 0.38 | F11: 0.35 | G11: 0.33 | H11: 0.2 | I11: 0.32 | J11: 0.3 | K11: 0.3 | L11: 0.27 | M11: 0.29 | N11: 0.28 | O11: 0.25 | P11: 0.24 | Q11: 0.26 | R11: 0.25 | S11: 0.22 | T11: 0.24 | U11: 0.18 | V11: 0.22 | W11: 0.2 | X11: 0.2 | Y11: 0.2 | Z11: 0.19 | AA11: 0.18 | AB11: 0.15 | AC11: 0.16 | AD11: 0.16 | AE11: 0.15 | AF11: 0.14 | AG11: 0.12 | AH11: 0.1 | AI11: 0.1 | AJ11: 0.08 | AK11: 0.06 | AL11: 0.05 | AM11: 0.04
A12: Detroit | B12: 0.45 | C12: 0.38 | D12: 0.32 | E12: 0.35 | F12: 0.3 | G12: 0.28 | H12: 0.3 | I12: 0.26 | J12: 0.28 | K12: 0.27 | L12: 0.26 | M12: 0.25 | N12: 0.24 | O12: 0.25 | P12: 0.22 | Q12: 0.2 | R12: 0.2 | S12: 0.19 | T12: 0.18 | U12: 0.16 | V12: 0.15 | W12: 0.16 | X12: 0.15 | Y12: 0.14 | Z12: 0.14 | AA12: 0.14 | AB12: 0.13 | AC12: 0.12 | AD12: 0.13 | AE12: 0.14 | AF12: 0.13 | AG12: 0.12 | AH12: 0.11 | AI12: 0.12 | AJ12: 0.15 | AK12: 0.12 | AL12: 0.11 | AM12: 0.1 | AN12: 0.14 | AO12: 0.11 | AP12: 0.09 | AQ12: 0.1 | AR12: 0.09 | AS12: 0.08 | AT12: 0.09 | AU12: 0.08 | AV12: 0.08 | AW12: 0.06 | AX12: 0.07 | AY12: 0.05
A13: Hawaii | B13: 0.28 | C13: 0.25 | D13: 0.22 | E13: 0.2 | F13: 0.2 | G13: 0.18 | H13: 0.18 | I13: 0.15 | J13: 0.14 | K13: 0.14 | L13: 0.15 | M13: 0.12 | N13: 0.12 | O13: 0.11 | P13: 0.1 | Q13: 0.1 | R13: 0.1 | S13: 0.1 | T13: 0.1 | U13: 0.09 | V13: 0.09 | W13: 0.09 | X13: 0.08 | Y13: 0.08 | Z13: 0.08 | AA13: 0.08 | AB13: 0.07 | AC13: 0.07 | AD13: 0.06 | AE13: 0.06 | AF13: 0.05 | AG13: 0.05
A14: Houston | B14: 0.38 | C14: 0.32 | D14: 0.28 | E14: 0.22 | F14: 0.2 | G14: 0.19 | H14: 0.2 | I14: 0.18 | J14: 0.18 | K14: 0.16 | L14: 0.17 | M14: 0.14 | N14: 0.15 | O14: 0.16 | P14: 0.13 | Q14: 0.15 | R14: 0.18 | S14: 0.15 | T14: 0.13 | U14: 0.14 | V14: 0.14 | W14: 0.12 | X14: 0.12 | Y14: 0.1 | Z14: 0.12 | AA14: 0.12 | AB14: 0.11 | AC14: 0.11 | AD14: 0.1 | AE14: 0.1 | AF14: 0.09 | AG14: 0.1 | AH14: 0.1 | AI14: 0.08 | AJ14: 0.09 | AK14: 0.07 | AL14: 0.08 | AM14: 0.06 | AN14: 0.04
A15: Indianapolis | B15: 0.3 | C15: 0.32 | D15: 0.25 | E15: 0.28 | F15: 0.26 | G15: 0.28 | H15: 0.23 | I15: 0.22 | J15: 0.24 | K15: 0.22 | L15: 0.2 | M15: 0.18 | N15: 0.2 | O15: 0.22 | P15: 0.17 | Q15: 0.15 | R15: 0.18 | S15: 0.16 | T15: 0.14 | U15: 0.15 | V15: 0.14 | W15: 0.13 | X15: 0.13 | Y15: 0.12 | Z15: 0.12 | AA15: 0.14 | AB15: 0.11 | AC15: 0.11 | AD15: 0.1 | AE15: 0.1 | AF15: 0.11 | AG15: 0.1 | AH15: 0.09 | AI15: 0.1 | AJ15: 0.09 | AK15: 0.08 | AL15: 0.08 | AM15: 0.1 | AN15: 0.07 | AO15: 0.07 | AP15: 0.05
A16: Kansas City | B16: 0.38 | C16: 0.35 | D16: 0.33 | E16: 0.3 | F16: 0.32 | G16: 0.29 | H16: 0.27 | I16: 0.26 | J16: 0.28 | K16: 0.25 | L16: 0.25 | M16: 0.24 | N16: 0.23 | O16: 0.21 | P16: 0.22 | Q16: 0.19 | R16: 0.2 | S16: 0.2 | T16: 0.18 | U16: 0.18 | V16: 0.19 | W16: 0.17 | X16: 0.17 | Y16: 0.16 | Z16: 0.18 | AA16: 0.16 | AB16: 0.15 | AC16: 0.15 | AD16: 0.15 | AE16: 0.14 | AF16: 0.13 | AG16: 0.14 | AH16: 0.15 | AI16: 0.12 | AJ16: 0.12 | AK16: 0.11 | AL16: 0.11 | AM16: 0.1 | AN16: 0.12 | AO16: 0.1 | AP16: 0.1 | AQ16: 0.09 | AR16: 0.08 | AS16: 0.08 | AT16: 0.07 | AU16: 0.07 | AV16: 0.06 | AW16: 0.08 | AX16: 0.06 | AY16: 0.05 | AZ16: 0.05 | BA16: 0.04 | BB16: 0.04 | BC16: 0.05
A17: Los Angeles | B17: 0.28 | C17: 0.24 | D17: 0.22 | E17: 0.25 | F17: 0.2 | G17: 0.22 | H17: 0.2 | I17: 0.18 | J17: 0.18 | K17: 0.15 | L17: 0.17 | M17: 0.16 | N17: 0.15 | O17: 0.12 | P17: 0.15 | Q17: 0.14 | R17: 0.14 | S17: 0.14 | T17: 0.12 | U17: 0.12 | V17: 0.1 | W17: 0.12 | X17: 0.1 | Y17: 0.09 | Z17: 0.11 | AA17: 0.1 | AB17: 0.1 | AC17: 0.09 | AD17: 0.1 | AE17: 0.09 | AF17: 0.08 | AG17: 0.07 | AH17: 0.08 | AI17: 0.07 | AJ17: 0.08 | AK17: 0.08 | AL17: 0.07 | AM17: 0.07 | AN17: 0.06 | AO17: 0.05 | AP17: 0.05 | AQ17: 0.04 | AR17: 0.04 | AS17: 0.04 | AT17: 0.03 | AU17: 0.03 | AV17: 0.02 | AW17: 0.02 | AX17: 0.02 | AY17: 0.02 | AZ17: 0.02 | BA17: 0.02 | BB17: 0.01 | BC17: 0.02 | BD17: 0.01
A18: Las Vegas | B18: 0.18 | C18: 0.14 | D18: 0.11 | E18: 0.12 | F18: 0.1 | G18: 0.1 | H18: 0.09 | I18: 0.09 | J18: 0.09 | K18: 0.08 | L18: 0.08 | M18: 0.05 | N18: 0.07 | O18: 0.06 | P18: 0.07 | Q18: 0.04 | R18: 0.04 | S18: 0.04 | T18: 0.03 | U18: 0.03 | V18: 0.03 | W18: 0.03 | X18: 0.03 | Y18: 0.02 | Z18: 0.02 | AA18: 0.02 | AB18: 0.02 | AC18: 0.02 | AD18: 0.01 | AE18: 0.01 | AF18: 0.01 | AG18: 0.01 | AH18: 0.01 | AI18: 0.01 | AJ18: 0.01
A19: Miami | B19: 0.45 | C19: 0.38 | D19: 0.4 | E19: 0.35 | F19: 0.32 | G19: 0.3 | H19: 0.3 | I19: 0.28 | J19: 0.25 | K19: 0.22 | L19: 0.22 | M19: 0.2 | N19: 0.2 | O19: 0.18 | P19: 0.16 | Q19: 0.2 | R19: 0.18 | S19: 0.17 | T19: 0.18 | U19: 0.15 | V19: 0.14 | W19: 0.14 | X19: 0.15 | Y19: 0.15 | Z19: 0.16 | AA19: 0.14 | AB19: 0.13 | AC19: 0.14 | AD19: 0.13 | AE19: 0.12 | AF19: 0.12 | AG19: 0.12 | AH19: 0.12 | AI19: 0.11 | AJ19: 0.1 | AK19: 0.1 | AL19: 0.1 | AM19: 0.1 | AN19: 0.09 | AO19: 0.08 | AP19: 0.09 | AQ19: 0.08 | AR19: 0.08 | AS19: 0.07 | AT19: 0.07
A20: Milwaukee | B20: 0.3 | C20: 0.28 | D20: 0.25 | E20: 0.22 | F20: 0.2 | G20: 0.18 | H20: 0.2 | I20: 0.16 | J20: 0.2 | K20: 0.15 | L20: 0.18 | M20: 0.14 | N20: 0.15 | O20: 0.16 | P20: 0.12 | Q20: 0.14 | R20: 0.13 | S20: 0.12 | T20: 0.11 | U20: 0.11 | V20: 0.11 | W20: 0.1 | X20: 0.12 | Y20: 0.1 | Z20: 0.09 | AA20: 0.1 | AB20: 0.09 | AC20: 0.12 | AD20: 0.09 | AE20: 0.08 | AF20: 0.08 | AG20: 0.1 | AH20: 0.08 | AI20: 0.07 | AJ20: 0.07 | AK20: 0.07 | AL20: 0.06 | AM20: 0.07 | AN20: 0.06 | AO20: 0.06 | AP20: 0.06 | AQ20: 0.05 | AR20: 0.05
A21: Nashville | B21: 0.45 | C21: 0.42 | D21: 0.4 | E21: 0.38 | F21: 0.35 | G21: 0.35 | H21: 0.3 | I21: 0.32 | J21: 0.28 | K21: 0.28 | L21: 0.25 | M21: 0.26 | N21: 0.22 | O21: 0.2 | P21: 0.2 | Q21: 0.19 | R21: 0.18 | S21: 0.15 | T21: 0.17 | U21: 0.12 | V21: 0.16 | W21: 0.15 | X21: 0.14 | Y21: 0.13 | Z21: 0.1 | AA21: 0.11 | AB21: 0.11 | AC21: 0.1 | AD21: 0.08 | AE21: 0.06
A22: New Orleans | B22: 0.45 | C22: 0.4 | D22: 0.35 | E22: 0.38 | F22: 0.3 | G22: 0.28 | H22: 0.25 | I22: 0.22 | J22: 0.2 | K22: 0.18 | L22: 0.18 | M22: 0.17 | N22: 0.15 | O22: 0.14 | P22: 0.16 | Q22: 0.12 | R22: 0.15 | S22: 0.11 | T22: 0.14 | U22: 0.1 | V22: 0.12 | W22: 0.12 | X22: 0.08 | Y22: 0.1 | Z22: 0.1 | AA22: 0.09 | AB22: 0.09 | AC22: 0.08 | AD22: 0.07 | AE22: 0.08 | AF22: 0.07 | AG22: 0.08 | AH22: 0.07 | AI22: 0.06 | AJ22: 0.06 | AK22: 0.06 | AL22: 0.06 | AM22: 0.06 | AN22: 0.05 | AO22: 0.05 | AP22: 0.05 | AQ22: 0.05 | AR22: 0.04 | AS22: 0.04 | AT22: 0.04 | AU22: 0.04 | AV22: 0.04 | AW22: 0.03
A23: NYC | B23: 0.45 | C23: 0.3 | D23: 0.35 | E23: 0.42 | F23: 0.4 | G23: 0.35 | H23: 0.32 | I23: 0.3 | J23: 0.38 | K23: 0.35 | L23: 0.25 | M23: 0.28 | N23: 0.25 | O23: 0.25 | P23: 0.22 | Q23: 0.2 | R23: 0.18 | S23: 0.18 | T23: 0.15 | U23: 0.18 | V23: 0.15 | W23: 0.12 | X23: 0.12 | Y23: 0.1 | Z23: 0.09 | AA23: 0.08 | AB23: 0.07 | AC23: 0.06 | AD23: 0.04 | AE23: 0.05 | AF23: 0.05 | AG23: 0.04 | AH23: 0.03 | AI23: 0.02
A24: Orlando | B24: 0.4 | C24: 0.35 | D24: 0.3 | E24: 0.28 | F24: 0.28 | G24: 0.25 | H24: 0.22 | I24: 0.2 | J24: 0.2 | K24: 0.2 | L24: 0.18 | M24: 0.18 | N24: 0.25 | O24: 0.16 | P24: 0.14 | Q24: 0.15 | R24: 0.16 | S24: 0.15 | T24: 0.14 | U24: 0.15 | V24: 0.14 | W24: 0.12 | X24: 0.12 | Y24: 0.12 | Z24: 0.12 | AA24: 0.1 | AB24: 0.1 | AC24: 0.1 | AD24: 0.09 | AE24: 0.1 | AF24: 0.08 | AG24: 0.09 | AH24: 0.08 | AI24: 0.08 | AJ24: 0.07 | AK24: 0.07 | AL24: 0.07 | AM24: 0.06 | AN24: 0.06 | AO24: 0.06 | AP24: 0.06 | AQ24: 0.05 | AR24: 0.05 | AS24: 0.05 | AT24: 0.04 | AU24: 0.04
A25: Philadelphia | B25: 0.4 | C25: 0.35 | D25: 0.38 | E25: 0.32 | F25: 0.3 | G25: 0.3 | H25: 0.28 | I25: 0.24 | J25: 0.22 | K25: 0.25 | L25: 0.17 | M25: 0.2 | N25: 0.2 | O25: 0.2 | P25: 0.2 | Q25: 0.16 | R25: 0.18 | S25: 0.16 | T25: 0.18 | U25: 0.16 | V25: 0.15 | W25: 0.15 | X25: 0.15 | Y25: 0.14 | Z25: 0.14 | AA25: 0.15 | AB25: 0.14 | AC25: 0.14 | AD25: 0.13 | AE25: 0.18 | AF25: 0.13 | AG25: 0.12 | AH25: 0.12 | AI25: 0.15 | AJ25: 0.12 | AK25: 0.1 | AL25: 0.11 | AM25: 0.12 | AN25: 0.12 | AO25: 0.11 | AP25: 0.12 | AQ25: 0.09 | AR25: 0.1 | AS25: 0.1 | AT25: 0.08 | AU25: 0.1 | AV25: 0.09 | AW25: 0.08 | AX25: 0.09 | AY25: 0.1 | AZ25: 0.08 | BA25: 0.08 | BB25: 0.08 | BC25: 0.07 | BD25: 0.07 | BE25: 0.07
A26: Phoenix | B26: 0.6 | C26: 0.58 | D26: 0.57 | E26: 0.56 | F26: 0.55 | G26: 0.54 | H26: 0.54 | I26: 0.53 | J26: 0.52 | K26: 0.38 | L26: 0.5 | M26: 0.37 | N26: 0.36 | O26: 0.48 | P26: 0.35 | Q26: 0.4 | R26: 0.34 | S26: 0.35 | T26: 0.32 | U26: 0.33 | V26: 0.3 | W26: 0.31 | X26: 0.28 | Y26: 0.25 | Z26: 0.26 | AA26: 0.22 | AB26: 0.24 | AC26: 0.2 | AD26: 0.2 | AE26: 0.18 | AF26: 0.15 | AG26: 0.17 | AH26: 0.18 | AI26: 0.19 | AJ26: 0.16 | AK26: 0.16 | AL26: 0.15 | AM26: 0.14 | AN26: 0.14 | AO26: 0.13 | AP26: 0.12 | AQ26: 0.12 | AR26: 0.11 | AS26: 0.1 | AT26: 0.1 | AU26: 0.09 | AV26: 0.08 | AW26: 0.08 | AX26: 0.07
A27: Portland | B27: 0.5 | C27: 0.45 | D27: 0.4 | E27: 0.33 | F27: 0.38 | G27: 0.36 | H27: 0.3 | I27: 0.35 | J27: 0.25 | K27: 0.32 | L27: 0.28 | M27: 0.24 | N27: 0.3 | O27: 0.28 | P27: 0.25 | Q27: 0.26 | R27: 0.22 | S27: 0.2 | T27: 0.2 | U27: 0.19 | V27: 0.18 | W27: 0.17 | X27: 0.16 | Y27: 0.1 | Z27: 0.15 | AA27: 0.15 | AB27: 0.14 | AC27: 0.12 | AD27: 0.13 | AE27: 0.12 | AF27: 0.1 | AG27: 0.1 | AH27: 0.09 | AI27: 0.09 | AJ27: 0.08 | AK27: 0.07 | AL27: 0.06 | AM27: 0.06 | AN27: 0.05
A28: San Antonio | B28: 0.45 | C28: 0.35 | D28: 0.3 | E28: 0.25 | F28: 0.22 | G28: 0.28 | H28: 0.2 | I28: 0.22 | J28: 0.2 | K28: 0.18 | L28: 0.16 | M28: 0.18 | N28: 0.15 | O28: 0.16 | P28: 0.14 | Q28: 0.15 | R28: 0.15 | S28: 0.12 | T28: 0.12 | U28: 0.14 | V28: 0.11 | W28: 0.1 | X28: 0.12 | Y28: 0.12 | Z28: 0.1 | AA28: 0.1 | AB28: 0.09 | AC28: 0.09 | AD28: 0.09 | AE28: 0.08 | AF28: 0.08 | AG28: 0.08 | AH28: 0.08 | AI28: 0.09 | AJ28: 0.1 | AK28: 0.08 | AL28: 0.07 | AM28: 0.07 | AN28: 0.07 | AO28: 0.07 | AP28: 0.06 | AQ28: 0.06 | AR28: 0.06 | AS28: 0.05 | AT28: 0.05 | AU28: 0.04 | AV28: 0.04 | AW28: 0.03
A29: San Diego | B29: 0.28 | C29: 0.25 | D29: 0.22 | E29: 0.2 | F29: 0.18 | G29: 0.17 | H29: 0.16 | I29: 0.15 | J29: 0.15 | K29: 0.14 | L29: 0.13 | M29: 0.12 | N29: 0.12 | O29: 0.11 | P29: 0.11 | Q29: 0.11 | R29: 0.1 | S29: 0.1 | T29: 0.1 | U29: 0.1 | V29: 0.09 | W29: 0.09 | X29: 0.09 | Y29: 0.08 | Z29: 0.08 | AA29: 0.07 | AB29: 0.07 | AC29: 0.07 | AD29: 0.06 | AE29: 0.07 | AF29: 0.05 | AG29: 0.06 | AH29: 0.06 | AI29: 0.06 | AJ29: 0.05 | AK29: 0.05 | AL29: 0.05 | AM29: 0.05 | AN29: 0.05 | AO29: 0.05 | AP29: 0.04 | AQ29: 0.04 | AR29: 0.04 | AS29: 0.04 | AT29: 0.04 | AU29: 0.04 | AV29: 0.03 | AW29: 0.03 | AX29: 0.02 | AY29: 0.03 | AZ29: 0.02 | BA29: 0.02 | BB29: 0.02 | BC29: 0.01 | BD29: 0.01
A30: Seattle | B30: 0.5 | C30: 0.55 | D30: 0.45 | E30: 0.42 | F30: 0.38 | G30: 0.4 | H30: 0.35 | I30: 0.3 | J30: 0.28 | K30: 0.28 | L30: 0.25 | M30: 0.26 | N30: 0.24 | O30: 0.24 | P30: 0.22 | Q30: 0.23 | R30: 0.2 | S30: 0.2 | T30: 0.18 | U30: 0.2 | V30: 0.19 | W30: 0.18 | X30: 0.15 | Y30: 0.16 | Z30: 0.17 | AA30: 0.15 | AB30: 0.14 | AC30: 0.14 | AD30: 0.13 | AE30: 0.12 | AF30: 0.11 | AG30: 0.1 | AH30: 0.1 | AI30: 0.1 | AJ30: 0.08 | AK30: 0.09 | AL30: 0.07 | AM30: 0.08 | AN30: 0.06 | AO30: 0.08 | AP30: 0.07 | AQ30: 0.06 | AR30: 0.05 | AS30: 0.03 | AT30: 0.02

Sheet T15_Public_School
A1: Atlanta | B1: Austin | C1: Bay Area | D1: Boston | E1: Charleston | F1: Chicago | G1: Cincinnati | H1: Cleveland | I1: Dallas | J1: DC | K1: Denver | L1: Detroit | M1: Hawaii | N1: Houston | O1: Indianapolis | P1: Kansas City | Q1: Los Angeles | R1: Las Vegas | S1: Miami | T1: Milwaukee | U1: Nashville | V1: New Orleans | W1: NYC | X1: Orlando | Y1: Philadelphia | Z1: Phoenix | AA1: Portland | AB1: San Antonio | AC1: San Diego | AD1: Seattle
A2: 0.15 | B2: 0.18 | C2: 0.13 | D2: 0.15 | E2: 0.2 | F2: 0.1 | G2: 0.15 | H2: 0.12 | I2: 0.15 | J2: 0.05 | K2: 0.18 | L2: 0.2 | M2: 0.07 | N2: 0.16 | O2: 0.12 | P2: 0.14 | Q2: 0.12 | R2: 0.07 | S2: 0.15 | T2: 0.12 | U2: 0.18 | V2: 0.18 | W2: 0.14 | X2: 0.12 | Y2: 0.2 | Z2: 0.25 | AA2: 0.15 | AB2: 0.18 | AC2: 0.12 | AD2: 0.2
A3: 0.12 | B3: 0.13 | C3: 0.12 | D3: 0.12 | E3: 0.15 | F3: 0.09 | G3: 0.12 | H3: 0.15 | I3: 0.12 | J3: 0.08 | K3: 0.15 | L3: 0.15 | M3: 0.08 | N3: 0.1 | O3: 0.18 | P3: 0.12 | Q3: 0.09 | R3: 0.05 | S3: 0.12 | T3: 0.1 | U3: 0.15 | V3: 0.12 | W3: 0.25 | X3: 0.1 | Y3: 0.15 | Z3: 0.22 | AA3: 0.2 | AB3: 0.15 | AC3: 0.11 | AD3: 0.1
A4: 0.11 | B4: 0.11 | C4: 0.12 | D4: 0.11 | E4: 0.08 | F4: 0.08 | G4: 0.14 | H4: 0.1 | I4: 0.1 | J4: 0.07 | K4: 0.14 | L4: 0.18 | M4: 0.06 | N4: 0.12 | O4: 0.1 | P4: 0.11 | Q4: 0.11 | R4: 0.02 | S4: 0.1 | T4: 0.15 | U4: 0.12 | V4: 0.15 | W4: 0.18 | X4: 0.1 | Y4: 0.12 | Z4: 0.21 | AA4: 0.15 | AB4: 0.12 | AC4: 0.1 | AD4: 0.15
A5: 0.1 | B5: 0.12 | C5: 0.11 | D5: 0.13 | E5: 0.1 | F5: 0.06 | G5: 0.08 | H5: 0.11 | I5: 0.09 | J5: 0.1 | K5: 0.1 | L5: 0.1 | M5: 0.06 | N5: 0.09 | O5: 0.16 | P5: 0.13 | Q5: 0.08 | R5: 0.04 | S5: 0.25 | T5: 0.08 | U5: 0.11 | V5: 0.1 | W5: 0.12 | X5: 0.09 | Y5: 0.16 | Z5: 0.2 | AA5: 0.18 | AB5: 0.1 | AC5: 0.09 | AD5: 0.12
A6: 0.09 | B6: 0.09 | C6: 0.1 | D6: 0.11 | E6: 0.05 | F6: 0.07 | G6: 0.1 | H6: 0.09 | I6: 0.08 | J6: 0.06 | K6: 0.12 | L6: 0.2 | M6: 0.05 | N6: 0.08 | O6: 0.14 | P6: 0.1 | Q6: 0.1 | R6: 0.03 | S6: 0.08 | T6: 0.12 | U6: 0.12 | V6: 0.09 | W6: 0.09 | X6: 0.09 | Y6: 0.14 | Z6: 0.2 | AA6: 0.14 | AB6: 0.08 | AC6: 0.08 | AD6: 0.12
A7: 0.09 | B7: 0.1 | C7: 0.1 | D7: 0.09 | E7: 0.05 | F7: 0.08 | G7: 0.12 | H7: 0.08 | I7: 0.11 | J7: 0.06 | K7: 0.12 | L7: 0.15 | M7: 0.05 | N7: 0.08 | O7: 0.15 | P7: 0.09 | Q7: 0.07 | R7: 0.03 | S7: 0.2 | T7: 0.06 | U7: 0.1 | V7: 0.08 | W7: 0.1 | X7: 0.08 | Y7: 0.1 | Z7: 0.19 | AA7: 0.1 | AB7: 0.14 | AC7: 0.08 | AD7: 0.1
A8: 0.08 | B8: 0.06 | C8: 0.09 | D8: 0.09 | E8: 0.06 | F8: 0.05 | G8: 0.09 | H8: 0.1 | I8: 0.1 | J8: 0.06 | K8: 0.15 | L8: 0.08 | M8: 0.04 | N8: 0.08 | O8: 0.09 | P8: 0.08 | Q8: 0.06 | R8: 0.03 | S8: 0.08 | T8: 0.05 | U8: 0.1 | V8: 0.08 | W8: 0.12 | X8: 0.07 | Y8: 0.13 | Z8: 0.19 | AA8: 0.12 | AB8: 0.09 | AC8: 0.07 | AD8: 0.08
A9: 0.12 | B9: 0.08 | C9: 0.07 | D9: 0.09 | E9: 0.04 | F9: 0.06 | G9: 0.08 | H9: 0.07 | I9: 0.07 | J9: 0.06 | K9: 0.07 | L9: 0.14 | M9: 0.03 | N9: 0.07 | O9: 0.08 | P9: 0.08 | Q9: 0.07 | R9: 0.02 | S9: 0.09 | T9: 0.05 | U9: 0.08 | V9: 0.06 | W9: 0.15 | X9: 0.06 | Y9: 0.12 | Z9: 0.18 | AA9: 0.09 | AB9: 0.1 | AC9: 0.07 | AD9: 0.07
A10: 0.08 | B10: 0.07 | C10: 0.08 | D10: 0.12 | E10: 0.04 | F10: 0.07 | G10: 0.07 | H10: 0.07 | I10: 0.07 | J10: 0.03 | K10: 0.08 | L10: 0.12 | M10: 0.04 | N10: 0.07 | O10: 0.11 | P10: 0.08 | Q10: 0.06 | R10: 0.03 | S10: 0.07 | T10: 0.08 | U10: 0.09 | V10: 0.05 | W10: 0.08 | X10: 0.15 | Y10: 0.09 | Z10: 0.18 | AA10: 0.15 | AB10: 0.09 | AC10: 0.06 | AD10: 0.05
A11: 0.08 | B11: 0.05 | C11: 0.06 | D11: 0.1 | E11: 0.03 | F11: 0.04 | G11: 0.06 | H11: 0.06 | I11: 0.06 | J11: 0.05 | K11: 0.08 | L11: 0.13 | M11: 0.04 | N11: 0.07 | O11: 0.09 | P11: 0.1 | Q11: 0.07 | R11: 0.02 | S11: 0.07 | T11: 0.04 | U11: 0.06 | V11: 0.05 | W11: 0.1 | X11: 0.06 | Y11: 0.1 | Z11: 0.18 | AA11: 0.08 | AB11: 0.07 | AC11: 0.06 | AD11: 0.06
A12: 0.07 | B12: 0.07 | C12: 0.08 | D12: 0.08 | E12: 0.04 | F12: 0.04 | G12: 0.05 | H12: 0.05 | I12: 0.09 | J12: 0.08 | K12: 0.1 | L12: 0.07 | M12: 0.03 | N12: 0.07 | O12: 0.08 | P12: 0.07 | Q12: 0.05 | R12: 0.02 | S12: 0.06 | T12: 0.07 | U12: 0.08 | V12: 0.04 | W12: 0.2 | X12: 0.05 | Y12: 0.06 | Z12: 0.17 | AA12: 0.1 | AB12: 0.06 | AC12: 0.06 | AD12: 0.1
A13: 0.11 | B13: 0.07 | C13: 0.08 | D13: 0.09 | E13: 0.03 | F13: 0.04 | G13: 0.05 | H13: 0.06 | I13: 0.08 | J13: 0.06 | K13: 0.06 | L13: 0.07 | M13: 0.03 | N13: 0.06 | O13: 0.06 | P13: 0.07 | Q13: 0.06 | R13: 0.08 | S13: 0.06 | T13: 0.04 | U13: 0.05 | V13: 0.04 | W13: 0.15 | X13: 0.05 | Y13: 0.08 | Z13: 0.17 | AA13: 0.1 | AB13: 0.07 | AC13: 0.05 | AD13: 0.06
... A31: 0.05 | B31: 0.03 | C31: 0.04 | D31: 0.03 | E31: 0.01 | F31: 0.04 | G31: 0.01 | H31: 0.02 | I31: 0.04 | J31: 0.03 | K31: 0.03 | L31: 0.04 | M31: 0.01 | N31: 0.04 | O31: 0.03 | P31: 0.04 | Q31: 0.03 | R31: 0 | S31: 0.03 | T31: 0.01 | U31: 0.01 | V31: 0.01 | W31: 0.02 | X31: 0.02 | Y31: 0.07 | Z31: 0.03 | AA31: 0.02 | AB31: 0.03 | AC31: 0.02 | AD31: 0.02
A32: 0.06 | B32: 0.02 | C32: 0.04 | D32: 0.05 | E32: 0.01 | F32: 0.03 | G32: 0.01 | H32: 0.02 | I32: 0.04 | J32: 0.03 | K32: 0.02 | L32: 0.03 | M32: 0.01 | N32: 0.03 | O32: 0.03 | P32: 0.03 | Q32: 0.03 | R32: 0 | S32: 0.04 | T32: 0.01 | V32: 0.02 | W32: 0.03 | X32: 0.02 | Y32: 0.05 | Z32: 0.03 | AA32: 0.01 | AB32: 0.03 | AC32: 0.02 | AD32: 0.02
A33: 0.04 | B33: 0.03 | C33: 0.05 | D33: 0.06 | E33: 0.01 | F33: 0.03 | G33: 0.01 | H33: 0.02 | I33: 0.05 | J33: 0.02 | K33: 0.02 | L33: 0.03 | M33: 0.01 | N33: 0.04 | O33: 0.03 | P33: 0.05 | Q33: 0.04 | R33: 0 | S33: 0.03 | T33: 0.04 | V33: 0.01 | W33: 0.01 | X33: 0.02 | Y33: 0.04 | Z33: 0.03 | AA33: 0.01 | AB33: 0.03 | AC33: 0.02 | AD33: 0.04
A34: 0.04 | B34: 0.02 | C34: 0.05 | D34: 0.07 | E34: 0.01 | F34: 0.03 | G34: 0.01 | H34: 0.02 | I34: 0.03 | J34: 0.03 | K34: 0.02 | L34: 0.03 | N34: 0.03 | O34: 0.02 | P34: 0.06 | Q34: 0.03 | R34: 0 | S34: 0.03 | T34: 0.02 | V34: 0.01 | W34: 0.01 | X34: 0.02 | Y34: 0.04 | Z34: 0.03 | AA34: 0.01 | AB34: 0.03 | AC34: 0.02 | AD34: 0.02
A35: 0.04 | B35: 0.02 | C35: 0.04 | D35: 0.04 | E35: 0.01 | F35: 0.03 | G35: 0.01 | H35: 0.04 | I35: 0.03 | J35: 0.03 | K35: 0.01 | L35: 0.03 | N35: 0.03 | O35: 0.03 | P35: 0.03 | Q35: 0.03 | R35: 0 | S35: 0.03 | T35: 0.01 | V35: 0.02 | W35: 0.01 | X35: 0.02 | Y35: 0.05 | Z35: 0.04 | AA35: 0.01 | AB35: 0.03 | AC35: 0.02 | AD35: 0.02
A36: 0.04 | B36: 0.02 | C36: 0.04 | D36: 0.05 | E36: 0.01 | F36: 0.02 | G36: 0.01 | H36: 0.02 | I36: 0.03 | J36: 0.02 | K36: 0.01 | L36: 0.05 | N36: 0.02 | O36: 0.02 | P36: 0.04 | Q36: 0.02 | R36: 0 | S36: 0.03 | T36: 0.01 | V36: 0.02 | X36: 0.02 | Y36: 0.08 | Z36: 0.02 | AA36: 0.01 | AB36: 0.04 | AC36: 0.01 | AD36: 0.03
A37: 0.03 | B37: 0.02 | C37: 0.03 | D37: 0.04 | E37: 0.01 | F37: 0.03 | G37: 0.01 | H37: 0.01 | I37: 0.03 | J37: 0.03 | K37: 0.01 | L37: 0.03 | N37: 0.02 | O37: 0.02 | P37: 0.03 | Q37: 0.02 | S37: 0.03 | T37: 0.01 | V37: 0.01 | X37: 0.02 | Y37: 0.05 | Z37: 0.02 | AA37: 0.01 | AB37: 0.03 | AC37: 0.02 | AD37: 0.01
A38: 0.03 | B38: 0.02 | C38: 0.04 | D38: 0.04 | E38: 0.01 | F38: 0.02 | G38: 0.01 | H38: 0.01 | I38: 0.03 | J38: 0.02 | K38: 0.01 | L38: 0.02 | N38: 0.02 | O38: 0.02 | P38: 0.03 | Q38: 0.03 | S38: 0.03 | T38: 0.01 | V38: 0.01 | X38: 0.01 | Y38: 0.04 | Z38: 0.02 | AA38: 0.01 | AB38: 0.02 | AC38: 0.02 | AD38: 0.02
A39: 0.02 | B39: 0.02 | C39: 0.04 | D39: 0.06 | E39: 0.01 | F39: 0.02 | G39: 0.01 | H39: 0.02 | I39: 0.03 | J39: 0.05 | K39: 0.01 | L39: 0.02 | N39: 0.02 | O39: 0.02 | P39: 0.02 | Q39: 0.03 | S39: 0.02 | T39: 0.01 | V39: 0.01 | X39: 0.01 | Y39: 0.04 | Z39: 0.03 | AA39: 0.01 | AB39: 0.02 | AC39: 0.01 | AD39: 0.01
A40: 0.02 | B40: 0.02 | C40: 0.04 | D40: 0.04 | E40: 0 | F40: 0.02 | G40: 0 | H40: 0.01 | I40: 0.03 | J40: 0.02 | L40: 0.06 | N40: 0.01 | O40: 0.01 | P40: 0.03 | Q40: 0.02 | S40: 0.02 | T40: 0.01 | V40: 0.01 | X40: 0.01 | Y40: 0.04 | Z40: 0.02 | AA40: 0.01 | AB40: 0.02 | AC40: 0.01 | AD40: 0.02
A41: 0.05 | B41: 0.02 | C41: 0.04 | D41: 0.04 | E41: 0 | F41: 0.02 | H41: 0.01 | I41: 0.02 | J41: 0.02 | L41: 0.02 | O41: 0.01 | P41: 0.03 | Q41: 0.02 | S41: 0.02 | T41: 0.01 | V41: 0.01 | X41: 0.01 | Y41: 0.04 | Z41: 0.02 | AB41: 0.02 | AC41: 0.02 | AD41: 0.01
A42: 0.08 | B42: 0.02 | C42: 0.04 | D42: 0.03 | F42: 0.02 | H42: 0.01 | I42: 0.03 | J42: 0.02 | L42: 0.02 | O42: 0.01 | P42: 0.03 | Q42: 0.02 | S42: 0.02 | T42: 0.01 | V42: 0.01 | X42: 0.01 | Y42: 0.04 | Z42: 0.02 | AB42: 0.02 | AC42: 0.01 | AD42: 0.01
A43: 0.02 | B43: 0.02 | C43: 0.03 | D43: 0.03 | F43: 0.02 | H43: 0.02 | I43: 0.03 | J43: 0.04 | L43: 0.02 | P43: 0.02 | Q43: 0.01 | S43: 0.02 | T43: 0.01 | V43: 0.01 | X43: 0.01 | Y43: 0.03 | Z43: 0.01 | AB43: 0.02 | AC43: 0 | AD43: 0.01
A44: 0.02 | B44: 0.02 | C44: 0.03 | D44: 0.02 | F44: 0.02 | H44: 0.03 | I44: 0.03 | J44: 0.02 | L44: 0.02 | P44: 0.02 | Q44: 0.01 | S44: 0.02 | T44: 0.01 | V44: 0.01 | X44: 0.01 | Y44: 0.03 | Z44: 0.01 | AB44: 0.02 | AC44: 0.01 | AD44: 0.01
A45: 0.01 | B45: 0.01 | C45: 0.03 | D45: 0.02 | F45: 0.02 | H45: 0.01 | I45: 0.03 | J45: 0.01 | L45: 0.02 | P45: 0.02 | Q45: 0.01 | S45: 0.02 | V45: 0.01 | X45: 0.01 | Y45: 0.03 | Z45: 0.01 | AB45: 0.02 | AC45: 0.01 | AD45: 0.01
A46: 0.01 | B46: 0.01 | C46: 0.03 | D46: 0.02 | F46: 0.02 | H46: 0.01 | I46: 0.02 | J46: 0.02 | L46: 0.03 | P46: 0.02 | Q46: 0.01 | S46: 0.02 | V46: 0.01 | X46: 0.01 | Y46: 0.02 | Z46: 0.01 | AB46: 0.02 | AC46: 0.01 | AD46: 0.01
A47: 0.01 | B47: 0.01 | C47: 0.03 | D47: 0.03 | F47: 0.03 | H47: 0.01 | I47: 0.03 | J47: 0.02 | L47: 0.01 | P47: 0.01 | Q47: 0.01 | V47: 0.01 | X47: 0.01 | Y47: 0.07 | Z47: 0.01 | AB47: 0.01 | AC47: 0.01
A48: 0.03 | B48: 0.01 | C48: 0.02 | D48: 0.02 | F48: 0.02 | H48: 0.01 | I48: 0.02 | J48: 0.02 | L48: 0.08 | P48: 0.01 | Q48: 0 | V48: 0.01 | Y48: 0.03 | Z48: 0.01 | AB48: 0.01 | AC48: 0.01
A49: 0.01 | B49: 0.01 | C49: 0.03 | D49: 0.01 | F49: 0.02 | H49: 0.01 | I49: 0.02 | J49: 0.01 | L49: 0.01 | P49: 0.02 | Q49: 0 | V49: 0.01 | Y49: 0.03 | Z49: 0.01 | AB49: 0.01 | AC49: 0.01
A50: 0.02 | B50: 0.01 | C50: 0.02 | D50: 0.01 | F50: 0.02 | H50: 0.01 | I50: 0.02 | L50: 0.02 | P50: 0.01 | Q50: 0 | Y50: 0.03 | Z50: 0.01 | AC50: 0.01
A51: 0.02 | B51: 0.01 | C51: 0.03 | D51: 0.01 | F51: 0.02 | H51: 0.01 | I51: 0.02 | L51: 0.02 | P51: 0.01 | Q51: 0 | Y51: 0.04 | AC51: 0.01
A52: 0.03 | B52: 0 | C52: 0.02 | D52: 0.02 | F52: 0.02 | H52: 0.02 | I52: 0.02 | P52: 0.01 | Q52: 0 | Y52: 0.03 | AC52: 0
A53: 0.02 | B53: 0 | C53: 0.03 | D53: 0.01 | F53: 0.02 | H53: 0.01 | I53: 0.01 | P53: 0.01 | Q53: 0 | Y53: 0.02 | AC53: 0.01
A54: 0.01 | C54: 0.02 | D54: 0 | F54: 0.02 | H54: 0.01 | P54: 0.01 | Q54: 0 | Y54: 0.02 | AC54: 0.01
A55: 0.01 | C55: 0.02 | D55: 0.01 | F55: 0.02 | H55: 0.01 | P55: 0.01 | Q55: 0.01 | Y55: 0.02 | AC55: 0
A56: 0.01 | C56: 0.02 | D56: 0.01 | F56: 0.02 | H56: 0.01 | Q56: 0 | Y56: 0.01 | AC56: 0
C57: 0.01 | D57: 0.01 | F57: 0.01 | H57: 0.01 | Y57: 0.02
...

Sheet T15_Public_School_T
A1: Atlanta | B1: 0.15 | C1: 0.12 | D1: 0.11 | E1: 0.1 | F1: 0.09 | G1: 0.09 | H1: 0.08 | I1: 0.12 | J1: 0.08 | K1: 0.08 | L1: 0.07 | M1: 0.11 | N1: 0.09 | O1: 0.07 | P1: 0.07 | Q1: 0.15 | R1: 0.05 | S1: 0.1 | T1: 0.06 | U1: 0.08 | V1: 0.06 | W1: 0.06 | X1: 0.06 | Y1: 0.07 | Z1: 0.04 | AA1: 0.08 | AB1: 0.07 | AC1: 0.05 | AD1: 0.05 | AE1: 0.05 | AF1: 0.06 | AG1: 0.04 | AH1: 0.04 | AI1: 0.04 | AJ1: 0.04 | AK1: 0.03 | AL1: 0.03 | AM1: 0.02 | AN1: 0.02 | AO1: 0.05 | AP1: 0.08 | AQ1: 0.02 | AR1: 0.02 | AS1: 0.01 | AT1: 0.01 | AU1: 0.01 | AV1: 0.03 | AW1: 0.01 | AX1: 0.02 | AY1: 0.02 | AZ1: 0.03 | BA1: 0.02 | BB1: 0.01 | BC1: 0.01 | BD1: 0.01
A2: Austin | B2: 0.18 | C2: 0.13 | D2: 0.11 | E2: 0.12 | F2: 0.09 | G2: 0.1 | H2: 0.06 | I2: 0.08 | J2: 0.07 | K2: 0.05 | L2: 0.07 | M2: 0.07 | N2: 0.05 | O2: 0.08 | P2: 0.05 | Q2: 0.05 | R2: 0.04 | S2: 0.04 | T2: 0.04 | U2: 0.06 | V2: 0.04 | W2: 0.04 | X2: 0.04 | Y2: 0.03 | Z2: 0.04 | AA2: 0.04 | AB2: 0.03 | AC2: 0.03 | AD2: 0.03 | AE2: 0.03 | AF2: 0.02 | AG2: 0.03 | AH2: 0.02 | AI2: 0.02 | AJ2: 0.02 | AK2: 0.02 | AL2: 0.02 | AM2: 0.02 | AN2: 0.02 | AO2: 0.02 | AP2: 0.02 | AQ2: 0.02 | AR2: 0.02 | AS2: 0.01 | AT2: 0.01 | AU2: 0.01 | AV2: 0.01 | AW2: 0.01 | AX2: 0.01 | AY2: 0.01 | AZ2: 0 | BA2: 0
A3: Bay Area | B3: 0.13 | C3: 0.12 | D3: 0.12 | E3: 0.11 | F3: 0.1 | G3: 0.1 | H3: 0.09 | I3: 0.07 | J3: 0.08 | K3: 0.06 | L3: 0.08 | M3: 0.08 | N3: 0.09 | O3: 0.06 | P3: 0.08 | Q3: 0.08 | R3: 0.05 | S3: 0.05 | T3: 0.07 | U3: 0.05 | V3: 0.07 | W3: 0.04 | X3: 0.07 | Y3: 0.06 | Z3: 0.07 | AA3: 0.06 | AB3: 0.06 | AC3: 0.03 | AD3: 0.04 | AE3: 0.04 | AF3: 0.04 | AG3: 0.05 | AH3: 0.05 | AI3: 0.04 | AJ3: 0.04 | AK3: 0.03 | AL3: 0.04 | AM3: 0.04 | AN3: 0.04 | AO3: 0.04 | AP3: 0.04 | AQ3: 0.03 | AR3: 0.03 | AS3: 0.03 | AT3: 0.03 | AU3: 0.03 | AV3: 0.02 | AW3: 0.03 | AX3: 0.02 | AY3: 0.03 | AZ3: 0.02 | BA3: 0.03 | BB3: 0.02 | BC3: 0.02 | BD3: 0.02 | BE3: 0.01 | BF3: 0.02 | BG3: 0.02 | BH3: 0.01 | BI3: 0.01 | BJ3: 0.01 | BK3: 0.01 | BL3: 0.01 | BM3: 0.01 | BN3: 0.01 | BO3: 0.01 | BP3: 0.01 | BQ3: 0 | BR3: 0 | BS3: 0
A4: Boston | B4: 0.15 | C4: 0.12 | D4: 0.11 | E4: 0.13 | F4: 0.11 | G4: 0.09 | H4: 0.09 | I4: 0.09 | J4: 0.12 | K4: 0.1 | L4: 0.08 | M4: 0.09 | N4: 0.08 | O4: 0.1 | P4: 0.11 | Q4: 0.09 | R4: 0.1 | S4: 0.08 | T4: 0.06 | U4: 0.08 | V4: 0.07 | W4: 0.08 | X4: 0.05 | Y4: 0.07 | Z4: 0.05 | AA4: 0.06 | AB4: 0.08 | AC4: 0.06 | AD4: 0.05 | AE4: 0.03 | AF4: 0.05 | AG4: 0.06 | AH4: 0.07 | AI4: 0.04 | AJ4: 0.05 | AK4: 0.04 | AL4: 0.04 | AM4: 0.06 | AN4: 0.04 | AO4: 0.04 | AP4: 0.03 | AQ4: 0.03 | AR4: 0.02 | AS4: 0.02 | AT4: 0.02 | AU4: 0.03 | AV4: 0.02 | AW4: 0.01 | AX4: 0.01 | AY4: 0.01 | AZ4: 0.02 | BA4: 0.01 | BB4: 0 | BC4: 0.01 | BD4: 0.01 | BE4: 0.01 | BF4: 0.01 | BG4: 0.01 | BH4: 0 | BI4: 0 | BJ4: 0 | BK4: 0 | BL4: 0 | BM4: 0 | BN4: 0 | BO4: 0 | BP4: 0
A5: Charleston | B5: 0.2 | C5: 0.15 | D5: 0.08 | E5: 0.1 | F5: 0.05 | G5: 0.05 | H5: 0.06 | I5: 0.04 | J5: 0.04 | K5: 0.03 | L5: 0.04 | M5: 0.03 | N5: 0.03 | O5: 0.02 | P5: 0.03 | Q5: 0.03 | R5: 0.02 | S5: 0.02 | T5: 0.02 | U5: 0.02 | V5: 0.02 | W5: 0.03 | X5: 0.02 | Y5: 0.01 | Z5: 0.01 | AA5: 0.02 | AB5: 0.01 | AC5: 0.01 | AD5: 0.02 | AE5: 0.01 | AF5: 0.01 | AG5: 0.01 | AH5: 0.01 | AI5: 0.01 | AJ5: 0.01 | AK5: 0.01 | AL5: 0.01 | AM5: 0.01 | AN5: 0 | AO5: 0
A6: Chicago | B6: 0.1 | C6: 0.09 | D6: 0.08 | E6: 0.06 | F6: 0.07 | G6: 0.08 | H6: 0.05 | I6: 0.06 | J6: 0.07 | K6: 0.04 | L6: 0.04 | M6: 0.04 | N6: 0.05 | O6: 0.07 | P6: 0.04 | Q6: 0.04 | R6: 0.04 | S6: 0.05 | T6: 0.05 | U6: 0.04 | V6: 0.06 | W6: 0.04 | X6: 0.03 | Y6: 0.04 | Z6: 0.04 | AA6: 0.03 | AB6: 0.03 | AC6: 0.03 | AD6: 0.03 | AE6: 0.04 | AF6: 0.03 | AG6: 0.03 | AH6: 0.03 | AI6: 0.03 | AJ6: 0.02 | AK6: 0.03 | AL6: 0.02 | AM6: 0.02 | AN6: 0.02 | AO6: 0.02 | AP6: 0.02 | AQ6: 0.02 | AR6: 0.02 | AS6: 0.02 | AT6: 0.02 | AU6: 0.03 | AV6: 0.02 | AW6: 0.02 | AX6: 0.02 | AY6: 0.02 | AZ6: 0.02 | BA6: 0.02 | BB6: 0.02 | BC6: 0.02 | BD6: 0.02 | BE6: 0.01 | BF6: 0.02 | BG6: 0.01 | BH6: 0.01 | BI6: 0.02 | BJ6: 0.01 | BK6: 0.01 | BL6: 0.01 | BM6: 0.01 | BN6: 0.01 | BO6: 0.01 | BP6: 0.01 | BQ6: 0.01 | BR6: 0 | BS6: 0 | BT6: 0
A7: Cincinnati | B7: 0.15 | C7: 0.12 | D7: 0.14 | E7: 0.08 | F7: 0.1 | G7: 0.12 | H7: 0.09 | I7: 0.08 | J7: 0.07 | K7: 0.06 | L7: 0.05 | M7: 0.05 | N7: 0.04 | O7: 0.04 | P7: 0.04 | Q7: 0.1 | R7: 0.03 | S7: 0.03 | T7: 0.02 | U7: 0.02 | V7: 0.02 | W7: 0.02 | X7: 0.02 | Y7: 0.02 | Z7: 0.04 | AA7: 0.01 | AB7: 0.02 | AC7: 0.02 | AD7: 0.01 | AE7: 0.01 | AF7: 0.01 | AG7: 0.01 | AH7: 0.01 | AI7: 0.01 | AJ7: 0.01 | AK7: 0.01 | AL7: 0.01 | AM7: 0.01 | AN7: 0
A8: Cleveland | B8: 0.12 | C8: 0.15 | D8: 0.1 | E8: 0.11 | F8: 0.09 | G8: 0.08 | H8: 0.1 | I8: 0.07 | J8: 0.07 | K8: 0.06 | L8: 0.05 | M8: 0.06 | N8: 0.05 | O8: 0.08 | P8: 0.04 | Q8: 0.04 | R8: 0.04 | S8: 0.03 | T8: 0.03 | U8: 0.03 | V8: 0.03 | W8: 0.03 | X8: 0.04 | Y8: 0.02 | Z8: 0.02 | AA8: 0.02 | AB8: 0.03 | AC8: 0.03 | AD8: 0.02 | AE8: 0.02 | AF8: 0.02 | AG8: 0.02 | AH8: 0.02 | AI8: 0.04 | AJ8: 0.02 | AK8: 0.01 | AL8: 0.01 | AM8: 0.02 | AN8: 0.01 | AO8: 0.01 | AP8: 0.01 | AQ8: 0.02 | AR8: 0.03 | AS8: 0.01 | AT8: 0.01 | AU8: 0.01 | AV8: 0.01 | AW8: 0.01 | AX8: 0.01 | AY8: 0.01 | AZ8: 0.02 | BA8: 0.01 | BB8: 0.01 | BC8: 0.01 | BD8: 0.01 | BE8: 0.01 | BF8: 0.01 | BG8: 0.01
A9: Dallas | B9: 0.15 | C9: 0.12 | D9: 0.1 | E9: 0.09 | F9: 0.08 | G9: 0.11 | H9: 0.1 | I9: 0.07 | J9: 0.07 | K9: 0.06 | L9: 0.09 | M9: 0.08 | N9: 0.06 | O9: 0.05 | P9: 0.06 | Q9: 0.06 | R9: 0.05 | S9: 0.05 | T9: 0.05 | U9: 0.05 | V9: 0.05 | W9: 0.05 | X9: 0.04 | Y9: 0.08 | Z9: 0.04 | AA9: 0.04 | AB9: 0.04 | AC9: 0.04 | AD9: 0.04 | AE9: 0.04 | AF9: 0.04 | AG9: 0.05 | AH9: 0.03 | AI9: 0.03 | AJ9: 0.03 | AK9: 0.03 | AL9: 0.03 | AM9: 0.03 | AN9: 0.03 | AO9: 0.02 | AP9: 0.03 | AQ9: 0.03 | AR9: 0.03 | AS9: 0.03 | AT9: 0.02 | AU9: 0.03 | AV9: 0.02 | AW9: 0.02 | AX9: 0.02 | AY9: 0.02 | AZ9: 0.02 | BA9: 0.01
A10: DC | B10: 0.05 | C10: 0.08 | D10: 0.07 | E10: 0.1 | F10: 0.06 | G10: 0.06 | H10: 0.06 | I10: 0.06 | J10: 0.03 | K10: 0.05 | L10: 0.08 | M10: 0.06 | N10: 0.05 | O10: 0.05 | P10: 0.05 | Q10: 0.04 | R10: 0.04 | S10: 0.04 | T10: 0.04 | U10: 0.04 | V10: 0.07 | W10: 0.03 | X10: 0.04 | Y10: 0.03 | Z10: 0.08 | AA10: 0.04 | AB10: 0.04 | AC10: 0.04 | AD10: 0.04 | AE10: 0.03 | AF10: 0.03 | AG10: 0.02 | AH10: 0.03 | AI10: 0.03 | AJ10: 0.02 | AK10: 0.03 | AL10: 0.02 | AM10: 0.05 | AN10: 0.02 | AO10: 0.02 | AP10: 0.02 | AQ10: 0.04 | AR10: 0.02 | AS10: 0.01 | AT10: 0.02 | AU10: 0.02 | AV10: 0.02 | AW10: 0.01
A11: Denver | B11: 0.18 | C11: 0.15 | D11: 0.14 | E11: 0.1 | F11: 0.12 | G11: 0.12 | H11: 0.15 | I11: 0.07 | J11: 0.08 | K11: 0.08 | L11: 0.1 | M11: 0.06 | N11: 0.07 | O11: 0.06 | P11: 0.08 | Q11: 0.06 | R11: 0.06 | S11: 0.09 | T11: 0.05 | U11: 0.08 | V11: 0.04 | W11: 0.04 | X11: 0.06 | Y11: 0.04 | Z11: 0.04 | AA11: 0.03 | AB11: 0.03 | AC11: 0.04 | AD11: 0.03 | AE11: 0.03 | AF11: 0.02 | AG11: 0.02 | AH11: 0.02 | AI11: 0.01 | AJ11: 0.01 | AK11: 0.01 | AL11: 0.01 | AM11: 0.01
A12: Detroit | B12: 0.2 | C12: 0.15 | D12: 0.18 | E12: 0.1 | F12: 0.2 | G12: 0.15 | H12: 0.08 | I12: 0.14 | J12: 0.12 | K12: 0.13 | L12: 0.07 | M12: 0.07 | N12: 0.09 | O12: 0.1 | P12: 0.06 | Q12: 0.1 | R12: 0.08 | S12: 0.06 | T12: 0.08 | U12: 0.05 | V12: 0.04 | W12: 0.05 | X12: 0.04 | Y12: 0.04 | Z12: 0.04 | AA12: 0.04 | AB12: 0.03 | AC12: 0.03 | AD12: 0.03 | AE12: 0.04 | AF12: 0.03 | AG12: 0.03 | AH12: 0.03 | AI12: 0.03 | AJ12: 0.05 | AK12: 0.03 | AL12: 0.02 | AM12: 0.02 | AN12: 0.06 | AO12: 0.02 | AP12: 0.02 | AQ12: 0.02 | AR12: 0.02 | AS12: 0.02 | AT12: 0.03 | AU12: 0.01 | AV12: 0.08 | AW12: 0.01 | AX12: 0.02 | AY12: 0.02
A13: Hawaii | B13: 0.07 | C13: 0.08 | D13: 0.06 | E13: 0.06 | F13: 0.05 | G13: 0.05 | H13: 0.04 | I13: 0.03 | J13: 0.04 | K13: 0.04 | L13: 0.03 | M13: 0.03 | N13: 0.03 | O13: 0.03 | P13: 0.02 | Q13: 0.02 | R13: 0.02 | S13: 0.02 | T13: 0.02 | U13: 0.02 | V13: 0.02 | W13: 0.02 | X13: 0.02 | Y13: 0.02 | Z13: 0.02 | AA13: 0.02 | AB13: 0.01 | AC13: 0.01 | AD13: 0.01 | AE13: 0.01 | AF13: 0.01 | AG13: 0.01
A14: Houston | B14: 0.16 | C14: 0.1 | D14: 0.12 | E14: 0.09 | F14: 0.08 | G14: 0.08 | H14: 0.08 | I14: 0.07 | J14: 0.07 | K14: 0.07 | L14: 0.07 | M14: 0.06 | N14: 0.06 | O14: 0.06 | P14: 0.06 | Q14: 0.05 | R14: 0.09 | S14: 0.05 | T14: 0.05 | U14: 0.05 | V14: 0.04 | W14: 0.05 | X14: 0.04 | Y14: 0.05 | Z14: 0.05 | AA14: 0.04 | AB14: 0.04 | AC14: 0.04 | AD14: 0.04 | AE14: 0.04 | AF14: 0.03 | AG14: 0.04 | AH14: 0.03 | AI14: 0.03 | AJ14: 0.02 | AK14: 0.02 | AL14: 0.02 | AM14: 0.02 | AN14: 0.01
A15: Indianapolis | B15: 0.12 | C15: 0.18 | D15: 0.1 | E15: 0.16 | F15: 0.14 | G15: 0.15 | H15: 0.09 | I15: 0.08 | J15: 0.11 | K15: 0.09 | L15: 0.08 | M15: 0.06 | N15: 0.05 | O15: 0.1 | P15: 0.05 | Q15: 0.05 | R15: 0.07 | S15: 0.04 | T15: 0.04 | U15: 0.04 | V15: 0.06 | W15: 0.04 | X15: 0.04 | Y15: 0.03 | Z15: 0.03 | AA15: 0.03 | AB15: 0.03 | AC15: 0.04 | AD15: 0.02 | AE15: 0.03 | AF15: 0.03 | AG15: 0.03 | AH15: 0.02 | AI15: 0.03 | AJ15: 0.02 | AK15: 0.02 | AL15: 0.02 | AM15: 0.02 | AN15: 0.01 | AO15: 0.01 | AP15: 0.01
A16: Kansas City | B16: 0.14 | C16: 0.12 | D16: 0.11 | E16: 0.13 | F16: 0.1 | G16: 0.09 | H16: 0.08 | I16: 0.08 | J16: 0.08 | K16: 0.1 | L16: 0.07 | M16: 0.07 | N16: 0.06 | O16: 0.06 | P16: 0.06 | Q16: 0.07 | R16: 0.05 | S16: 0.05 | T16: 0.05 | U16: 0.06 | V16: 0.05 | W16: 0.04 | X16: 0.05 | Y16: 0.04 | Z16: 0.05 | AA16: 0.05 | AB16: 0.05 | AC16: 0.06 | AD16: 0.04 | AE16: 0.04 | AF16: 0.03 | AG16: 0.05 | AH16: 0.06 | AI16: 0.03 | AJ16: 0.04 | AK16: 0.03 | AL16: 0.03 | AM16: 0.02 | AN16: 0.03 | AO16: 0.03 | AP16: 0.03 | AQ16: 0.02 | AR16: 0.02 | AS16: 0.02 | AT16: 0.02 | AU16: 0.01 | AV16: 0.01 | AW16: 0.02 | AX16: 0.01 | AY16: 0.01 | AZ16: 0.01 | BA16: 0.01 | BB16: 0.01 | BC16: 0.01
A17: Los Angeles | B17: 0.12 | C17: 0.09 | D17: 0.11 | E17: 0.08 | F17: 0.1 | G17: 0.07 | H17: 0.06 | I17: 0.07 | J17: 0.06 | K17: 0.07 | L17: 0.05 | M17: 0.06 | N17: 0.05 | O17: 0.08 | P17: 0.06 | Q17: 0.05 | R17: 0.05 | S17: 0.04 | T17: 0.04 | U17: 0.04 | V17: 0.05 | W17: 0.04 | X17: 0.04 | Y17: 0.04 | Z17: 0.02 | AA17: 0.03 | AB17: 0.03 | AC17: 0.04 | AD17: 0.02 | AE17: 0.03 | AF17: 0.03 | AG17: 0.04 | AH17: 0.03 | AI17: 0.03 | AJ17: 0.02 | AK17: 0.02 | AL17: 0.03 | AM17: 0.03 | AN17: 0.02 | AO17: 0.02 | AP17: 0.02 | AQ17: 0.01 | AR17: 0.01 | AS17: 0.01 | AT17: 0.01 | AU17: 0.01 | AV17: 0 | AW17: 0 | AX17: 0 | AY17: 0 | AZ17: 0 | BA17: 0 | BB17: 0 | BC17: 0.01 | BD17: 0
A18: Las Vegas | B18: 0.07 | C18: 0.05 | D18: 0.02 | E18: 0.04 | F18: 0.03 | G18: 0.03 | H18: 0.03 | I18: 0.02 | J18: 0.03 | K18: 0.02 | L18: 0.02 | M18: 0.08 | N18: 0.03 | O18: 0.02 | P18: 0.02 | Q18: 0.01 | R18: 0.01 | S18: 0.01 | T18: 0.01 | U18: 0.01 | V18: 0.01 | W18: 0.01 | X18: 0.01 | Y18: 0.01 | Z18: 0.01 | AA18: 0.01 | AB18: 0 | AC18: 0 | AD18: 0 | AE18: 0 | AF18: 0 | AG18: 0 | AH18: 0 | AI18: 0 | AJ18: 0
A19: Miami | B19: 0.15 | C19: 0.12 | D19: 0.1 | E19: 0.25 | F19: 0.08 | G19: 0.2 | H19: 0.08 | I19: 0.09 | J19: 0.07 | K19: 0.07 | L19: 0.06 | M19: 0.06 | N19: 0.05 | O19: 0.05 | P19: 0.05 | Q19: 0.06 | R19: 0.04 | S19: 0.05 | T19: 0.1 | U19: 0.05 | V19: 0.04 | W19: 0.04 | X19: 0.04 | Y19: 0.09 | Z19: 0.04 | AA19: 0.08 | AB19: 0.04 | AC19: 0.03 | AD19: 0.07 | AE19: 0.03 | AF19: 0.04 | AG19: 0.03 | AH19: 0.03 | AI19: 0.03 | AJ19: 0.03 | AK19: 0.03 | AL19: 0.03 | AM19: 0.02 | AN19: 0.02 | AO19: 0.02 | AP19: 0.02 | AQ19: 0.02 | AR19: 0.02 | AS19: 0.02 | AT19: 0.02
